Workbook
Name exp_assay: Assay!$C$11
Name exp_date: Assay!$C$2
Name exp_id: Assay!$C$7
Name exp_notes: Assay!$C$13
Name exp_rxns: Assay!$C$10
Name exp_summary: Assay!$C$6
Name exp_type: Reference!$B$20
Name exp_version: Reference!$B$21
Name pcr_enzyme: Assay!$C$12
Name pcr_primers: Assay!#REF!
Name pcr_primersource: Assay!#REF!
Name pcr_targetpanel: Assay!#REF!
Name Post_PCR_target_DNA_conc: Reference!$B$17
Name teamplate_max_vol: Reference!$F$31
Name template_vol: Assay!$D$18
Name user_initials: Assay!$C$4
Name user_name: Assay!$C$3

Sheet Assay
A1: NOMADS PCR Worksheet
A2: Date: | G2: (YYYY-MM-DD) | K2: KEY
A3: User: | G3: (enter name) | K3: Required fields
A4: User Initials: | C4: {=IF(ISBLANK(user_name),"",_xlfn.CONCAT(LEFT(_xlfn.TEXTSPLIT(TRIM(user_name)," "),1)))} | K4: Calculated fields
A5: Exp Number: | G5: (three digit ID created by the user) | K5: Do NOT use any commas
A6: Exp Summary: | G6: (enter human readable detail)
A7: Exp ID: | C7: =IF(OR(ISBLANK(C3),ISBLANK(C5)),"",CONCATENATE("PC",user_initials,C5)) | G7: (PC = PCR)
A8: Exp Name: | C8: =IF(OR(ISBLANK(C2),ISBLANK(C3),LEN(C7)=0),"",CONCATENATE(C2,"_",C7))
A9: Filename: | C9: =IF(OR(LEN(C8)=0,LEN(exp_summary)=0),"",CONCATENATE(C8,"_",exp_summary))
A10: Number of samples: | C10: =COUNTA(PCR!E4:E99) -> 0 | G10: (calculated from PCR tab)
A11: Assay Name: | C11: NOMADS_MVP | G11: (select from dropdown)
A12: PCR Enzyme: | C12: KAPA HiFi ReadyMix | G12: (select from dropdown)
A13: Notes:
A16: 1 -Multiplex PCR | C16: Overage | D16: 0.12
A17: Item | D17: Per tube (µl) | F17: =CONCATENATE("MM x",exp_rxns, " (µl)") -> MM x0 (µl) | J17: Temperature (oC) | L17: Time | M17: Cycles
A18: Template | D18: 8 | F18: - | J18: =Reference!E69 -> 95 | L18: =Reference!F69 -> ∞ | M18: =Reference!G69 -> 0
A19: =Reference!E32 -> KAPA HiFI ReadyMix (2x) | D19: =Reference!F32 -> 15.5 | F19: =IFERROR(SUM(D19*exp_rxns*(1+$D$16)),"") -> 0 | J19: =Reference!E70 -> 95 | L19: =Reference!F70 -> 3 min | M19: =Reference!G70 -> 0
A20: =Reference!E33 -> Primer pool (10 μM) | D20: =Reference!F33 -> 1.5 | F20: =IFERROR(SUM(D20*exp_rxns*(1+$D$16)),"") -> 0 | J20: =Reference!E71 -> 98 | L20: =Reference!F71 -> 20 sec | M20: =Reference!G71 -> x35
A21: =Reference!E34 -> Water | D21: =Reference!F34 -> 0 | F21: =IFERROR(SUM(D21*exp_rxns*(1+$D$16)),"") -> 0 | J21: =Reference!E72 -> 60 | L21: =Reference!F72 -> 3 min | M21: =Reference!G72 -> x35
A22: =Reference!E35 -> - | D22: =Reference!F35 -> 0 | F22: =IFERROR(SUM(D22*exp_rxns*(1+$D$16)),"") -> 0 | J22: =Reference!E73 -> 60 | L22: =Reference!F73 -> 10 min | M22: =Reference!G73 -> 0
A23: =Reference!E36 -> - | D23: =Reference!F36 -> 0 | F23: =IFERROR(SUM(D23*exp_rxns*(1+$D$16)),"") -> 0 | J23: =Reference!E74 -> 8 | L23: =Reference!F74 -> ∞ | M23: =Reference!G74 -> 0
C24: Total volume: | D24: =IF(SUM(D18:E23)=0,"",SUM(D18:E23)) -> 25 | F24: =CONCATENATE("Add ",SUM(D19:D23)," µl of MM to each well") -> Add 17 µl of MM to each well | J24: =Reference!E75 -> 0 | L24: =Reference!F75 -> 0 | M24: =Reference!G75 -> 0
A25: =_xlfn.CONCAT("(If dispensing MM from an 8-well strip tube with a multichannel, add ",ROUND((SUM(F18:G23)/8),0)," µl of MM to each strip tube well)") -> (If dispensing MM from an 8-well strip tube with a multichannel, add 0 µl of MM to each strip tube well)
A27: 2- Post-PCR
A28: 1. Run 1 µl of PCR product on a 1% agarose gel, picture and annotate it | K28: (Enter in Gel Image Tab)
A29: 2. Clean-up with 12 µl (0.5X) AMPPure beads per sample, mix and incubate at RT for 5 min. Pellet on magnet for 8 min and wash 2 x 200 µl 80% fresh EtoH, spin, dry, then re-suspend in 15 µl EB and transfer to fresh tube / well
A30: 3. Quantify 1 µl (199 µl WS 1X HS DNA). Dilute in NF H2O if required | K30: (Enter in PCR Tab)
A32: PCR | B32: Select ID to reference in platemap: | F32: Sample ID
B33: 1 | C33: 2 | D33: 3 | E33: 4 | F33: 5 | G33: 6 | H33: 7 | I33: 8 | J33: 9 | K33: 10 | L33: 11 | M33: 12
A34: A | B34: =PCR!$D4 | C34: =PCR!$D12 | D34: =PCR!$D20 | E34: =PCR!$D28 | F34: =PCR!$D36 | G34: =PCR!$D44 | H34: =PCR!$D52 | I34: =PCR!$D60 | J34: =PCR!$D68 | K34: =PCR!$D76 | L34: =PCR!$D84 | M34: =PCR!$D92
A35: B | B35: =PCR!$D5 | C35: =PCR!$D13 | D35: =PCR!$D21 | E35: =PCR!$D29 | F35: =PCR!$D37 | G35: =PCR!$D45 | H35: =PCR!$D53 | I35: =PCR!$D61 | J35: =PCR!$D69 | K35: =PCR!$D77 | L35: =PCR!$D85 | M35: =PCR!$D93
A36: C | B36: =PCR!$D6 | C36: =PCR!$D14 | D36: =PCR!$D22 | E36: =PCR!$D30 | F36: =PCR!$D38 | G36: =PCR!$D46 | H36: =PCR!$D54 | I36: =PCR!$D62 | J36: =PCR!$D70 | K36: =PCR!$D78 | L36: =PCR!$D86 | M36: =PCR!$D94
A37: D | B37: =PCR!$D7 | C37: =PCR!$D15 | D37: =PCR!$D23 | E37: =PCR!$D31 | F37: =PCR!$D39 | G37: =PCR!$D47 | H37: =PCR!$D55 | I37: =PCR!$D63 | J37: =PCR!$D71 | K37: =PCR!$D79 | L37: =PCR!$D87 | M37: =PCR!$D95
A38: E | B38: =PCR!$D8 | C38: =PCR!$D16 | D38: =PCR!$D24 | E38: =PCR!$D32 | F38: =PCR!$D40 | G38: =PCR!$D48 | H38: =PCR!$D56 | I38: =PCR!$D64 | J38: =PCR!$D72 | K38: =PCR!$D80 | L38: =PCR!$D88 | M38: =PCR!$D96
A39: F | B39: =PCR!$D9 | C39: =PCR!$D17 | D39: =PCR!$D25 | E39: =PCR!$D33 | F39: =PCR!$D41 | G39: =PCR!$D49 | H39: =PCR!$D57 | I39: =PCR!$D65 | J39: =PCR!$D73 | K39: =PCR!$D81 | L39: =PCR!$D89 | M39: =PCR!$D97
A40: G | B40: =PCR!$D10 | C40: =PCR!$D18 | D40: =PCR!$D26 | E40: =PCR!$D34 | F40: =PCR!$D42 | G40: =PCR!$D50 | H40: =PCR!$D58 | I40: =PCR!$D66 | J40: =PCR!$D74 | K40: =PCR!$D82 | L40: =PCR!$D90 | M40: =PCR!$D98
A41: H | B41: =PCR!$D11 | C41: =PCR!$D19 | D41: =PCR!$D27 | E41: =PCR!$D35 | F41: =PCR!$D43 | G41: =PCR!$D51 | H41: =PCR!$D59 | I41: =PCR!$D67 | J41: =PCR!$D75 | K41: =PCR!$D83 | L41: =PCR!$D91 | M41: =PCR!$D99

Sheet PCR
E1: Copy these columns to the library template
E2: Sample Information
A3: # | B3: Column | C3: Well | D3: Platemap ID | E3: Sample ID | F3: Extraction ID | G3: Sample Type | H3: PCR [DNA] (ng / µl) | I3: Qubit PCR [DNA] (ng/µl) | J3: PCR Dilution Factor
A4: 1 | B4: =RIGHT(tbl_PCR[[#This Row],[Well]],LEN(tbl_PCR[[#This Row],[Well]])-1) -> 1 | C4: A1 | D4: =IF(Assay!$F$32=Reference!$E$120,IF(LEN(tbl_PCR[[#This Row],[Sample ID]])>0,tbl_PCR[[#This Row],[Sample ID]],""),IF(LEN(tbl_PCR[[#This Row],[Extraction ID]])>0,tbl_PCR[[#This Row],[Extraction ID]],"")) | H4: =IF(OR(I4="",J4=""),"",SUM(I4*J4))
A5: 2 | B5: =RIGHT(tbl_PCR[[#This Row],[Well]],LEN(tbl_PCR[[#This Row],[Well]])-1) -> 1 | C5: B1 | D5: =IF(Assay!$F$32=Reference!$E$120,IF(LEN(tbl_PCR[[#This Row],[Sample ID]])>0,tbl_PCR[[#This Row],[Sample ID]],""),IF(LEN(tbl_PCR[[#This Row],[Extraction ID]])>0,tbl_PCR[[#This Row],[Extraction ID]],"")) | H5: =IF(OR(I5="",J5=""),"",SUM(I5*J5))
A6: 3 | B6: =RIGHT(tbl_PCR[[#This Row],[Well]],LEN(tbl_PCR[[#This Row],[Well]])-1) -> 1 | C6: C1 | D6: =IF(Assay!$F$32=Reference!$E$120,IF(LEN(tbl_PCR[[#This Row],[Sample ID]])>0,tbl_PCR[[#This Row],[Sample ID]],""),IF(LEN(tbl_PCR[[#This Row],[Extraction ID]])>0,tbl_PCR[[#This Row],[Extraction ID]],"")) | H6: =IF(OR(I6="",J6=""),"",SUM(I6*J6))
A7: 4 | B7: =RIGHT(tbl_PCR[[#This Row],[Well]],LEN(tbl_PCR[[#This Row],[Well]])-1) -> 1 | C7: D1 | D7: =IF(Assay!$F$32=Reference!$E$120,IF(LEN(tbl_PCR[[#This Row],[Sample ID]])>0,tbl_PCR[[#This Row],[Sample ID]],""),IF(LEN(tbl_PCR[[#This Row],[Extraction ID]])>0,tbl_PCR[[#This Row],[Extraction ID]],"")) | H7: =IF(OR(I7="",J7=""),"",SUM(I7*J7))
A8: 5 | B8: =RIGHT(tbl_PCR[[#This Row],[Well]],LEN(tbl_PCR[[#This Row],[Well]])-1) -> 1 | C8: E1 | D8: =IF(Assay!$F$32=Reference!$E$120,IF(LEN(tbl_PCR[[#This Row],[Sample ID]])>0,tbl_PCR[[#This Row],[Sample ID]],""),IF(LEN(tbl_PCR[[#This Row],[Extraction ID]])>0,tbl_PCR[[#This Row],[Extraction ID]],"")) | H8: =IF(OR(I8="",J8=""),"",SUM(I8*J8))
A9: 6 | B9: =RIGHT(tbl_PCR[[#This Row],[Well]],LEN(tbl_PCR[[#This Row],[Well]])-1) -> 1 | C9: F1 | D9: =IF(Assay!$F$32=Reference!$E$120,IF(LEN(tbl_PCR[[#This Row],[Sample ID]])>0,tbl_PCR[[#This Row],[Sample ID]],""),IF(LEN(tbl_PCR[[#This Row],[Extraction ID]])>0,tbl_PCR[[#This Row],[Extraction ID]],"")) | H9: =IF(OR(I9="",J9=""),"",SUM(I9*J9))
A10: 7 | B10: =RIGHT(tbl_PCR[[#This Row],[Well]],LEN(tbl_PCR[[#This Row],[Well]])-1) -> 1 | C10: G1 | D10: =IF(Assay!$F$32=Reference!$E$120,IF(LEN(tbl_PCR[[#This Row],[Sample ID]])>0,tbl_PCR[[#This Row],[Sample ID]],""),IF(LEN(tbl_PCR[[#This Row],[Extraction ID]])>0,tbl_PCR[[#This Row],[Extraction ID]],"")) | H10: =IF(OR(I10="",J10=""),"",SUM(I10*J10))
A11: 8 | B11: =RIGHT(tbl_PCR[[#This Row],[Well]],LEN(tbl_PCR[[#This Row],[Well]])-1) -> 1 | C11: H1 | D11: =IF(Assay!$F$32=Reference!$E$120,IF(LEN(tbl_PCR[[#This Row],[Sample ID]])>0,tbl_PCR[[#This Row],[Sample ID]],""),IF(LEN(tbl_PCR[[#This Row],[Extraction ID]])>0,tbl_PCR[[#This Row],[Extraction ID]],"")) | H11: =IF(OR(I11="",J11=""),"",SUM(I11*J11))
A12: 9 | B12: =RIGHT(tbl_PCR[[#This Row],[Well]],LEN(tbl_PCR[[#This Row],[Well]])-1) -> 2 | C12: A2 | D12: =IF(Assay!$F$32=Reference!$E$120,IF(LEN(tbl_PCR[[#This Row],[Sample ID]])>0,tbl_PCR[[#This Row],[Sample ID]],""),IF(LEN(tbl_PCR[[#This Row],[Extraction ID]])>0,tbl_PCR[[#This Row],[Extraction ID]],"")) | H12: =IF(OR(I12="",J12=""),"",SUM(I12*J12))
A13: 10 | B13: =RIGHT(tbl_PCR[[#This Row],[Well]],LEN(tbl_PCR[[#This Row],[Well]])-1) -> 2 | C13: B2 | D13: =IF(Assay!$F$32=Reference!$E$120,IF(LEN(tbl_PCR[[#This Row],[Sample ID]])>0,tbl_PCR[[#This Row],[Sample ID]],""),IF(LEN(tbl_PCR[[#This Row],[Extraction ID]])>0,tbl_PCR[[#This Row],[Extraction ID]],"")) | H13: =IF(OR(I13="",J13=""),"",SUM(I13*J13))
A14: 11 | B14: =RIGHT(tbl_PCR[[#This Row],[Well]],LEN(tbl_PCR[[#This Row],[Well]])-1) -> 2 | C14: C2 | D14: =IF(Assay!$F$32=Reference!$E$120,IF(LEN(tbl_PCR[[#This Row],[Sample ID]])>0,tbl_PCR[[#This Row],[Sample ID]],""),IF(LEN(tbl_PCR[[#This Row],[Extraction ID]])>0,tbl_PCR[[#This Row],[Extraction ID]],"")) | H14: =IF(OR(I14="",J14=""),"",SUM(I14*J14))
A15: 12 | B15: =RIGHT(tbl_PCR[[#This Row],[Well]],LEN(tbl_PCR[[#This Row],[Well]])-1) -> 2 | C15: D2 | D15: =IF(Assay!$F$32=Reference!$E$120,IF(LEN(tbl_PCR[[#This Row],[Sample ID]])>0,tbl_PCR[[#This Row],[Sample ID]],""),IF(LEN(tbl_PCR[[#This Row],[Extraction ID]])>0,tbl_PCR[[#This Row],[Extraction ID]],"")) | H15: =IF(OR(I15="",J15=""),"",SUM(I15*J15))
... A99: 96 | B99: =RIGHT(tbl_PCR[[#This Row],[Well]],LEN(tbl_PCR[[#This Row],[Well]])-1) -> 12 | C99: H12 | D99: =IF(Assay!$F$32=Reference!$E$120,IF(LEN(tbl_PCR[[#This Row],[Sample ID]])>0,tbl_PCR[[#This Row],[Sample ID]],""),IF(LEN(tbl_PCR[[#This Row],[Extraction ID]])>0,tbl_PCR[[#This Row],[Extraction ID]],"")) | H99: =IF(OR(I99="",J99=""),"",SUM(I99*J99))
D100: 1 | E100: Copy these columns to the library template

Sheet Gel

Sheet Reference
A1: Instructions
A2: This template is to be used to record PCR amplification as part of a NOMADS sequencing run.
A3: To prevent inadvertent loss of data, cells are protected from editing, you can only select unlocked cells, use tab to navigate
A5: Process
A6: 1. Enter all details into the 'Assay' (experiment level) and 'PCR' (reaction level) tabs, ensuring all yellow highlighted cells are complete
A7: - when copying from another worksheet, always right-click and paste VALUES:
A8: 2. Paste gel picture into the 'Gel' tab and label lanes
A9: - Crop the image to just the relevent areas
A10: - Compress by selecting the image: Picture format (ribbon) > Compress Pictures > Use these settings
A11: - Copy list of samples from 'PCR' tab. Paste Special with Transpose if converting from list to rows:
A14: Reference values (change only if required)
A15: Assumptions | E15: Look-ups
A16: Description | E16: DNA Source | G16: Assays
A17: Post-PCR clean-up target [DNA] | B17: 30 | C17: ng/ul | E17: sWGA product | G17: =E77 -> NOMADS8
E18: Extracted DNA | G18: =E85 -> NOMADS16
A19: Experiment | G19: =E94 -> NOMADS_MVP
A20: type | B20: PCR | E20: DNA Polymerase | G20: =E102 -> Anoph IR
A21: version | B21: 11 | E21: KAPA HiFi | G21: =E110 -> Anoph Speciation
E22: KAPA HiFi ReadyMix
A23: Changelog from previous version | E23: Q5
A24: Removed multiple details not being used
A25: Removed usernames and projects | E25: Sample Type
E26: Field
E27: Positive
E28: Negative
E30: Selected polymerase
E31: Template max vol (ul) | F31: =IF(pcr_enzyme=$E$21,F39,IF(pcr_enzyme=$E$22,F49,IF(pcr_enzyme=$E$23,F59,""))) -> 8
E32: =IF(pcr_enzyme=$E$21,E42,IF(pcr_enzyme=$E$22,E52,IF(pcr_enzyme=$E$23,E62,""))) -> KAPA HiFI ReadyMix (2x) | F32: =IF(pcr_enzyme=$E$21,F42,IF(pcr_enzyme=$E$22,F52,IF(pcr_enzyme=$E$23,F62,""))) -> 15.5
E33: =IF(pcr_enzyme=$E$21,E43,IF(pcr_enzyme=$E$22,E53,IF(pcr_enzyme=$E$23,E63,""))) -> Primer pool (10 μM) | F33: =IF(pcr_enzyme=$E$21,F43,IF(pcr_enzyme=$E$22,F53,IF(pcr_enzyme=$E$23,F63,""))) -> 1.5
E34: =IF(pcr_enzyme=$E$21,E44,IF(pcr_enzyme=$E$22,E54,IF(pcr_enzyme=$E$23,E64,""))) -> Water | F34: =IF(pcr_enzyme=$E$21,F44,IF(pcr_enzyme=$E$22,F54,IF(pcr_enzyme=$E$23,F64,""))) -> 0
E35: =IF(pcr_enzyme=$E$21,E45,IF(pcr_enzyme=$E$22,E55,IF(pcr_enzyme=$E$23,E65,""))) -> - | F35: =IF(pcr_enzyme=$E$21,F45,IF(pcr_enzyme=$E$22,F55,IF(pcr_enzyme=$E$23,F65,""))) -> 0
E36: =IF(pcr_enzyme=$E$21,E46,IF(pcr_enzyme=$E$22,E56,IF(pcr_enzyme=$E$23,E66,""))) -> - | F36: =IF(pcr_enzyme=$E$21,F46,IF(pcr_enzyme=$E$22,F56,IF(pcr_enzyme=$E$23,F66,""))) -> 0
E38: KAPA HiFi
E39: Template max vol (ul) | F39: 8
E40: Components (no water) | F40: =SUM(F42:F45) -> 7.55
E41: Rxn volume | F41: 25
E42: KAPA HiFi | F42: 0.3
E43: 10mM dNTPs | F43: 0.75
E44: Buffer | F44: 5
E45: Primer pool (10 μM) | F45: 1.5
...

Sheet expt_metadata
A1: expt_id | B1: expt_date | C1: expt_user | D1: expt_type | E1: expt_version | F1: expt_assay | G1: expt_notes | H1: expt_summary | I1: expt_rxns | J1: pcr_template_vol | K1: pcr_enzyme
A2: =IF(LEN(exp_id)=0,"",exp_id) | B2: =IF(LEN(exp_date)=0,"",exp_date) | C2: =IF(LEN(user_name)=0,"",user_name) | D2: =IF(LEN(exp_type)=0,"",exp_type) -> PCR | E2: =IF(LEN(exp_version)=0,"",exp_version) -> 11 | F2: =IF(LEN(exp_assay)=0,"",exp_assay) -> NOMADS_MVP | G2: =IF(LEN(exp_notes)=0,"",exp_notes) | H2: =IF(LEN(exp_summary)=0,"",exp_summary) | I2: =IF(LEN(exp_rxns)=0,"",exp_rxns) -> 0 | J2: =IF(LEN(template_vol)=0,"",template_vol) -> 8 | K2: =IF(pcr_enzyme=0,"",pcr_enzyme) -> KAPA HiFi ReadyMix

Sheet rxn_metadata
A1: sample_id | B1: extraction_id | C1: sample_type | D1: pcr_product_ngul
A2: =IF(LEN(PCR!E4),PCR!E4,"") | B2: =IF(LEN(PCR!F4),PCR!F4,"") | C2: =IF(LEN(PCR!G4),PCR!G4,"") | D2: =PCR!H4
A3: =IF(LEN(PCR!E5),PCR!E5,"") | B3: =IF(LEN(PCR!F5),PCR!F5,"") | C3: =IF(LEN(PCR!G5),PCR!G5,"") | D3: =PCR!H5
A4: =IF(LEN(PCR!E6),PCR!E6,"") | B4: =IF(LEN(PCR!F6),PCR!F6,"") | C4: =IF(LEN(PCR!G6),PCR!G6,"") | D4: =PCR!H6
A5: =IF(LEN(PCR!E7),PCR!E7,"") | B5: =IF(LEN(PCR!F7),PCR!F7,"") | C5: =IF(LEN(PCR!G7),PCR!G7,"") | D5: =PCR!H7
A6: =IF(LEN(PCR!E8),PCR!E8,"") | B6: =IF(LEN(PCR!F8),PCR!F8,"") | C6: =IF(LEN(PCR!G8),PCR!G8,"") | D6: =PCR!H8
A7: =IF(LEN(PCR!E9),PCR!E9,"") | B7: =IF(LEN(PCR!F9),PCR!F9,"") | C7: =IF(LEN(PCR!G9),PCR!G9,"") | D7: =PCR!H9
A8: =IF(LEN(PCR!E10),PCR!E10,"") | B8: =IF(LEN(PCR!F10),PCR!F10,"") | C8: =IF(LEN(PCR!G10),PCR!G10,"") | D8: =PCR!H10
A9: =IF(LEN(PCR!E11),PCR!E11,"") | B9: =IF(LEN(PCR!F11),PCR!F11,"") | C9: =IF(LEN(PCR!G11),PCR!G11,"") | D9: =PCR!H11
A10: =IF(LEN(PCR!E12),PCR!E12,"") | B10: =IF(LEN(PCR!F12),PCR!F12,"") | C10: =IF(LEN(PCR!G12),PCR!G12,"") | D10: =PCR!H12
A11: =IF(LEN(PCR!E13),PCR!E13,"") | B11: =IF(LEN(PCR!F13),PCR!F13,"") | C11: =IF(LEN(PCR!G13),PCR!G13,"") | D11: =PCR!H13
A12: =IF(LEN(PCR!E14),PCR!E14,"") | B12: =IF(LEN(PCR!F14),PCR!F14,"") | C12: =IF(LEN(PCR!G14),PCR!G14,"") | D12: =PCR!H14
A13: =IF(LEN(PCR!E15),PCR!E15,"") | B13: =IF(LEN(PCR!F15),PCR!F15,"") | C13: =IF(LEN(PCR!G15),PCR!G15,"") | D13: =PCR!H15
... A97: =IF(LEN(PCR!E99),PCR!E99,"") | B97: =IF(LEN(PCR!F99),PCR!F99,"") | C97: =IF(LEN(PCR!G99),PCR!G99,"") | D97: =PCR!H99
