Workbook
Name adaptlig_dna_maxvol: Reference!$B$18
Name adaptlig_rxn_vol: Assay!$F$41
Name adaptlig_targetmass: Assay!$B$41
Name DNAconc_library: Assay!$G$55
Name DNAconc_pooled: Assay!$D$38
Name endrepair_maxvol: Reference!$B$17
Name endrepair_targetmass: Assay!$F$15
Name exp_date: Assay!$C$2
Name exp_id: Assay!$C$7
Name exp_notes: Assay!$C$11
Name exp_rxns: Assay!$C$10
Name exp_subtype: Reference!$B$27
Name exp_summary: Assay!$C$6
Name exp_type: Reference!$B$26
Name exp_version: Reference!$B$28
Name flowcell_checkpores: Assay!$C$58
Name flowcell_chemisty: Assay!#REF!
Name flowcell_id: Assay!#REF!
Name flowcell_maxvol: Reference!$B$19
Name flowcell_runduration: Assay!#REF!
Name flowcell_status: Assay!#REF!
Name flowcell_targetmass: Assay!$B$65
Name flowcell_usage_hrs: Assay!#REF!
Name library_washbuffer: Assay!$C$51
Name Minimum_final_pooled_DNA_conc: Reference!$B$20
Name missing_qc_resolution: Reference!$B$23
Name Post_PCR_target_DNA_conc: Reference!$B$21
Name seq_platform: Assay!#REF!
Name user_initials: Assay!$C$4
Name user_name: Assay!$C$3
Name vol_calc: Reference!$B$22

Sheet Assay
A1: NOMADS Library Worksheet - Ligation
A2: Date: | G2: (YYYY-MM-DD) | J2: KEY
A3: User: | G3: (enter name) | J3: Required fields
A4: User Initials: | G4: (first last) | J4: Calculated fields
A5: Exp Number: | G5: (user created three digit ID) | J5: Do NOT use any commas in fields
A6: Exp Summary: | G6: (enter human readable detail)
A7: Exp ID: | C7: =IF(OR(ISBLANK(C3),ISBLANK(C5)),"",CONCATENATE("SL",user_initials,C5)) | G7: (SL = Sequencing Library)
A8: Exp Name: | C8: =IF(OR(ISBLANK(C2),ISBLANK(C3),ISBLANK(C5)),"",CONCATENATE(C2,"_",C7))
A9: Filename: | C9: {=IF(LEN(C8)=0,"",CONCATENATE(C8,"_",exp_summary))}
A10: Number of samples: | C10: =COUNTA(tbl_SeqLib[Sample ID]) -> 0 | G10: (calculated from Library tab)
A11: Notes:
A14: 1 - Library Preparation | I14: (Values in Library Tab)
A15: 1. Add PCR product per sample for end repair: | F15: 800 | G15: =CONCATENATE("ng added, max vol = ", endrepair_maxvol, " µl, max 800ng") -> ng added, max vol = 10 µl, max 800ng
A16: 2. End-repair rxn: | C16: Overage | D16: 0.1
A17: Item | D17: Per tube (µl) | F17: =CONCATENATE("MM x",exp_rxns," (µl)") -> MM x0 (µl) | I17: Temperature (oC) | K17: Time (min)
A18: PCR product | D18: x | F18: - | I18: 20 | K18: 15
A19: NF H20 | D19: =CONCATENATE(endrepair_maxvol, " - x") -> 10 - x | F19: - | I19: 65 | K19: 15
A20: NEBNext End repair reaction buffer (10x) | D20: 1.4 | F20: =SUM(D20*exp_rxns*(1+$D$16)) -> 0 | I20: 4 | K20: ∞
A21: NEBNext end prep enzyme mix | D21: 0.6 | F21: =SUM(D21*exp_rxns*(1+$D$16)) -> 0
D22: =SUM(D20:D21)+endrepair_maxvol -> 12 | F22: =CONCATENATE("Add ",SUM(D20:D21)," µl of MM to each") -> Add 2 µl of MM to each
A24: 3. Barcoding Ligation: | C24: Overage | D24: 0.1
A25: Item | D25: Per tube (µl) | F25: =CONCATENATE("MM x",exp_rxns," (µl)") -> MM x0 (µl) | I25: Temperature (oC) | K25: Time (min)
A26: Native Barcode (1-96) | D26: 0.5 | F26: - | I26: 20 | K26: 20
A27: Ultra II Ligation MM | D27: 6 | F27: =SUM(D27*exp_rxns*(1+$D$24)) -> 0 | I27: 65 | K27: 10
A28: Ultra II Ligation Enhancer | D28: 0.2 | F28: =SUM(D28*exp_rxns*(1+$D$24)) -> 0 | I28: 8 | K28: ∞
D29: =SUM(D26:D28)+D22 -> 18.7 | F29: =CONCATENATE("Add ",SUM(D27:D28)," µl of MM to each") -> Add 6.2 µl of MM to each
A31: 2 - Pooling and clean-up
A32: Sample vol (µl) | B32: Total vol (µl) | C32: Bead ratio (x) | D32: Total bead vol (µl) | E32: Incubation time (min) | F32: EtOH wash vol (µl) | G32: Resuspension vol (µl)
B33: =IF(OR(ISBLANK(A33),ISBLANK(exp_rxns)),"",SUM(A33*exp_rxns)) | C33: 0.4 | D33: =IFERROR(SUM(B33*C33),"")
A34: Pool: Combine equal volume of all samples into a new LoBind tube
A35: Clean up: Add AMPPure beads, at RT with mixing, wash twice in 80% EtOH, spin, dry, re-suspend in EB and transfer eluate to fresh tube
A36: Quantify: 1 µl as a 1:10 dilution on Qubit. Dilute further if required
A37: AMPPure Volume (µl) | B37: Pooled DNA (ng / µl) | C37: Dilution Factor | D37: Final Pooled [DNA] (ng/µl)*
A38: =SUM(exp_rxns*D29)*0.4 -> 0 | D38: =SUM(B38*C38) -> 0
A40: 3 - Adapter Ligation
A41: Added | C41: ng of product in rxn volume of | F41: 50 | G41: =_xlfn.CONCAT("µl (recommend 1500 ng of product in ",adaptlig_dna_maxvol," µl max)") -> µl (recommend 1500 ng of product in 30 µl max)
A42: Item | D42: Per tube (µl) | I42: Temperature (oC) | K42: Time (min)
A43: Barcoded pool | D43: =IF(B38="",adaptlig_dna_maxvol,IF(SUM(adaptlig_targetmass/D38)>adaptlig_dna_maxvol,adaptlig_dna_maxvol,SUM(adaptlig_targetmass/D38))) -> 30 | I43: RT | K43: 10
A44: NF H20 | D44: =IFERROR(SUM(adaptlig_dna_maxvol-D43),"") -> 0
A45: Ligation Adapter (NA) | D45: 5
...

Sheet Library
D1: Sample Information | H1: Library Prep
A2: # | B2: Column | C2: Well | D2: Sample ID | E2: Extraction ID | F2: Sample Type | G2: PCR [DNA] (ng / µl) | H2: Barcode# | I2: DNA conc present | J2: Sample ID present | K2: One or more entries in column | L2: Calculate | M2: Exact | N2: Max for col | O2: Avg per plate | P2: Max per plate | Q2: PCR product (µl) to add for end-repair (calculated) | R2: PCR product (µl) added (if different from calculated) | S2: NF H20 (µl) | T2: SeqLib Identifier
A3: 1 | B3: =RIGHT(tbl_SeqLib[[#This Row],[Well]],LEN(tbl_SeqLib[[#This Row],[Well]])-1) -> 1 | C3: A1 | H3: 01 | I3: =IF(LEN(tbl_SeqLib[[#This Row],[PCR '[DNA'] (ng / µl)]])>0,1,0) -> 0 | J3: =IF(LEN(tbl_SeqLib[[#This Row],[Sample ID]])>0,1,0) -> 0 | K3: =IF(SUMIF(tbl_SeqLib[Column],tbl_SeqLib[[#This Row],[Column]],tbl_SeqLib[DNA conc present])>0,1,0) -> 0 | L3: =IF(SUM(tbl_SeqLib[[#This Row],[DNA conc present]:[Sample ID present]])>0,1,0) -> 0 | M3: =IF(LEN(tbl_SeqLib[[#This Row],[PCR '[DNA'] (ng / µl)]])=0,"",IF(endrepair_targetmass/tbl_SeqLib[[#This Row],[PCR '[DNA'] (ng / µl)]]>endrepair_maxvol,endrepair_maxvol,ROUNDUP(SUM(endrepair_targetmass/tbl_SeqLib[[#This Row],[PCR '[DNA'] (ng / µl)]]),1))) | N3: =ROUNDDOWN(_xlfn.MAXIFS(tbl_SeqLib[Exact],tbl_SeqLib[Column],tbl_SeqLib[[#This Row],[Column]]),1) -> 0 | O3: =AVERAGE(tbl_SeqLib[Exact]) -> #DIV/0! | P3: =MAX(tbl_SeqLib[Exact]) -> 0 | Q3: =IF(AND(tbl_SeqLib[[#This Row],[Calculate]],LEN(tbl_SeqLib[[#This Row],[PCR product (µl) added (if different from calculated)]])=0),IF(vol_calc=Reference!$E$39,tbl_SeqLib[[#This Row],[Max per plate]],IF(vol_calc=Reference!$E$40,tbl_SeqLib[[#This Row],[Avg per plate]],IF(vol_calc=Reference!$E$38,tbl_SeqLib[[#This Row],[Max for col]],"ERROR"))),"") | S3: =IF(tbl_SeqLib[[#This Row],[Calculate]]=0,"",SUM(endrepair_maxvol-IF(tbl_SeqLib[[#This Row],[PCR product (µl) added (if different from calculated)]]>0,tbl_SeqLib[[#This Row],[PCR product (µl) added (if different from calculated)]],tbl_SeqLib[[#This Row],[PCR product (µl) to add for end-repair (calculated)]]))) | T3: =IF(ISBLANK(#REF!),"",CONCATENATE(exp_id,"_",tbl_SeqLib[[#This Row],[Well]])) -> _A1
A4: 2 | B4: =RIGHT(tbl_SeqLib[[#This Row],[Well]],LEN(tbl_SeqLib[[#This Row],[Well]])-1) -> 1 | C4: B1 | H4: 02 | I4: =IF(LEN(tbl_SeqLib[[#This Row],[PCR '[DNA'] (ng / µl)]])>0,1,0) -> 0 | J4: =IF(LEN(tbl_SeqLib[[#This Row],[Sample ID]])>0,1,0) -> 0 | K4: =IF(SUMIF(tbl_SeqLib[Column],tbl_SeqLib[[#This Row],[Column]],tbl_SeqLib[DNA conc present])>0,1,0) -> 0 | L4: =IF(SUM(tbl_SeqLib[[#This Row],[DNA conc present]:[Sample ID present]])>0,1,0) -> 0 | M4: =IF(LEN(tbl_SeqLib[[#This Row],[PCR '[DNA'] (ng / µl)]])=0,"",IF(endrepair_targetmass/tbl_SeqLib[[#This Row],[PCR '[DNA'] (ng / µl)]]>endrepair_maxvol,endrepair_maxvol,ROUNDUP(SUM(endrepair_targetmass/tbl_SeqLib[[#This Row],[PCR '[DNA'] (ng / µl)]]),1))) | N4: =ROUNDDOWN(_xlfn.MAXIFS(tbl_SeqLib[Exact],tbl_SeqLib[Column],tbl_SeqLib[[#This Row],[Column]]),1) -> 0 | O4: =AVERAGE(tbl_SeqLib[Exact]) -> #DIV/0! | P4: =MAX(tbl_SeqLib[Exact]) -> 0 | Q4: =IF(AND(tbl_SeqLib[[#This Row],[Calculate]],LEN(tbl_SeqLib[[#This Row],[PCR product (µl) added (if different from calculated)]])=0),IF(vol_calc=Reference!$E$39,tbl_SeqLib[[#This Row],[Max per plate]],IF(vol_calc=Reference!$E$40,tbl_SeqLib[[#This Row],[Avg per plate]],IF(vol_calc=Reference!$E$38,tbl_SeqLib[[#This Row],[Max for col]],"ERROR"))),"") | S4: =IF(tbl_SeqLib[[#This Row],[Calculate]]=0,"",SUM(endrepair_maxvol-IF(tbl_SeqLib[[#This Row],[PCR product (µl) added (if different from calculated)]]>0,tbl_SeqLib[[#This Row],[PCR product (µl) added (if different from calculated)]],tbl_SeqLib[[#This Row],[PCR product (µl) to add for end-repair (calculated)]]))) | T4: =IF(ISBLANK(#REF!),"",CONCATENATE(exp_id,"_",tbl_SeqLib[[#This Row],[Well]])) -> _B1
A5: 3 | B5: =RIGHT(tbl_SeqLib[[#This Row],[Well]],LEN(tbl_SeqLib[[#This Row],[Well]])-1) -> 1 | C5: C1 | H5: 03 | I5: =IF(LEN(tbl_SeqLib[[#This Row],[PCR '[DNA'] (ng / µl)]])>0,1,0) -> 0 | J5: =IF(LEN(tbl_SeqLib[[#This Row],[Sample ID]])>0,1,0) -> 0 | K5: =IF(SUMIF(tbl_SeqLib[Column],tbl_SeqLib[[#This Row],[Column]],tbl_SeqLib[DNA conc present])>0,1,0) -> 0 | L5: =IF(SUM(tbl_SeqLib[[#This Row],[DNA conc present]:[Sample ID present]])>0,1,0) -> 0 | M5: =IF(LEN(tbl_SeqLib[[#This Row],[PCR '[DNA'] (ng / µl)]])=0,"",IF(endrepair_targetmass/tbl_SeqLib[[#This Row],[PCR '[DNA'] (ng / µl)]]>endrepair_maxvol,endrepair_maxvol,ROUNDUP(SUM(endrepair_targetmass/tbl_SeqLib[[#This Row],[PCR '[DNA'] (ng / µl)]]),1))) | N5: =ROUNDDOWN(_xlfn.MAXIFS(tbl_SeqLib[Exact],tbl_SeqLib[Column],tbl_SeqLib[[#This Row],[Column]]),1) -> 0 | O5: =AVERAGE(tbl_SeqLib[Exact]) -> #DIV/0! | P5: =MAX(tbl_SeqLib[Exact]) -> 0 | Q5: =IF(AND(tbl_SeqLib[[#This Row],[Calculate]],LEN(tbl_SeqLib[[#This Row],[PCR product (µl) added (if different from calculated)]])=0),IF(vol_calc=Reference!$E$39,tbl_SeqLib[[#This Row],[Max per plate]],IF(vol_calc=Reference!$E$40,tbl_SeqLib[[#This Row],[Avg per plate]],IF(vol_calc=Reference!$E$38,tbl_SeqLib[[#This Row],[Max for col]],"ERROR"))),"") | S5: =IF(tbl_SeqLib[[#This Row],[Calculate]]=0,"",SUM(endrepair_maxvol-IF(tbl_SeqLib[[#This Row],[PCR product (µl) added (if different from calculated)]]>0,tbl_SeqLib[[#This Row],[PCR product (µl) added (if different from calculated)]],tbl_SeqLib[[#This Row],[PCR product (µl) to add for end-repair (calculated)]]))) | T5: =IF(ISBLANK(#REF!),"",CONCATENATE(exp_id,"_",tbl_SeqLib[[#This Row],[Well]])) -> _C1
A6: 4 | B6: =RIGHT(tbl_SeqLib[[#This Row],[Well]],LEN(tbl_SeqLib[[#This Row],[Well]])-1) -> 1 | C6: D1 | H6: 04 | I6: =IF(LEN(tbl_SeqLib[[#This Row],[PCR '[DNA'] (ng / µl)]])>0,1,0) -> 0 | J6: =IF(LEN(tbl_SeqLib[[#This Row],[Sample ID]])>0,1,0) -> 0 | K6: =IF(SUMIF(tbl_SeqLib[Column],tbl_SeqLib[[#This Row],[Column]],tbl_SeqLib[DNA conc present])>0,1,0) -> 0 | L6: =IF(SUM(tbl_SeqLib[[#This Row],[DNA conc present]:[Sample ID present]])>0,1,0) -> 0 | M6: =IF(LEN(tbl_SeqLib[[#This Row],[PCR '[DNA'] (ng / µl)]])=0,"",IF(endrepair_targetmass/tbl_SeqLib[[#This Row],[PCR '[DNA'] (ng / µl)]]>endrepair_maxvol,endrepair_maxvol,ROUNDUP(SUM(endrepair_targetmass/tbl_SeqLib[[#This Row],[PCR '[DNA'] (ng / µl)]]),1))) | N6: =ROUNDDOWN(_xlfn.MAXIFS(tbl_SeqLib[Exact],tbl_SeqLib[Column],tbl_SeqLib[[#This Row],[Column]]),1) -> 0 | O6: =AVERAGE(tbl_SeqLib[Exact]) -> #DIV/0! | P6: =MAX(tbl_SeqLib[Exact]) -> 0 | Q6: =IF(AND(tbl_SeqLib[[#This Row],[Calculate]],LEN(tbl_SeqLib[[#This Row],[PCR product (µl) added (if different from calculated)]])=0),IF(vol_calc=Reference!$E$39,tbl_SeqLib[[#This Row],[Max per plate]],IF(vol_calc=Reference!$E$40,tbl_SeqLib[[#This Row],[Avg per plate]],IF(vol_calc=Reference!$E$38,tbl_SeqLib[[#This Row],[Max for col]],"ERROR"))),"") | S6: =IF(tbl_SeqLib[[#This Row],[Calculate]]=0,"",SUM(endrepair_maxvol-IF(tbl_SeqLib[[#This Row],[PCR product (µl) added (if different from calculated)]]>0,tbl_SeqLib[[#This Row],[PCR product (µl) added (if different from calculated)]],tbl_SeqLib[[#This Row],[PCR product (µl) to add for end-repair (calculated)]]))) | T6: =IF(ISBLANK(#REF!),"",CONCATENATE(exp_id,"_",tbl_SeqLib[[#This Row],[Well]])) -> _D1
A7: 5 | B7: =RIGHT(tbl_SeqLib[[#This Row],[Well]],LEN(tbl_SeqLib[[#This Row],[Well]])-1) -> 1 | C7: E1 | H7: 05 | I7: =IF(LEN(tbl_SeqLib[[#This Row],[PCR '[DNA'] (ng / µl)]])>0,1,0) -> 0 | J7: =IF(LEN(tbl_SeqLib[[#This Row],[Sample ID]])>0,1,0) -> 0 | K7: =IF(SUMIF(tbl_SeqLib[Column],tbl_SeqLib[[#This Row],[Column]],tbl_SeqLib[DNA conc present])>0,1,0) -> 0 | L7: =IF(SUM(tbl_SeqLib[[#This Row],[DNA conc present]:[Sample ID present]])>0,1,0) -> 0 | M7: =IF(LEN(tbl_SeqLib[[#This Row],[PCR '[DNA'] (ng / µl)]])=0,"",IF(endrepair_targetmass/tbl_SeqLib[[#This Row],[PCR '[DNA'] (ng / µl)]]>endrepair_maxvol,endrepair_maxvol,ROUNDUP(SUM(endrepair_targetmass/tbl_SeqLib[[#This Row],[PCR '[DNA'] (ng / µl)]]),1))) | N7: =ROUNDDOWN(_xlfn.MAXIFS(tbl_SeqLib[Exact],tbl_SeqLib[Column],tbl_SeqLib[[#This Row],[Column]]),1) -> 0 | O7: =AVERAGE(tbl_SeqLib[Exact]) -> #DIV/0! | P7: =MAX(tbl_SeqLib[Exact]) -> 0 | Q7: =IF(AND(tbl_SeqLib[[#This Row],[Calculate]],LEN(tbl_SeqLib[[#This Row],[PCR product (µl) added (if different from calculated)]])=0),IF(vol_calc=Reference!$E$39,tbl_SeqLib[[#This Row],[Max per plate]],IF(vol_calc=Reference!$E$40,tbl_SeqLib[[#This Row],[Avg per plate]],IF(vol_calc=Reference!$E$38,tbl_SeqLib[[#This Row],[Max for col]],"ERROR"))),"") | S7: =IF(tbl_SeqLib[[#This Row],[Calculate]]=0,"",SUM(endrepair_maxvol-IF(tbl_SeqLib[[#This Row],[PCR product (µl) added (if different from calculated)]]>0,tbl_SeqLib[[#This Row],[PCR product (µl) added (if different from calculated)]],tbl_SeqLib[[#This Row],[PCR product (µl) to add for end-repair (calculated)]]))) | T7: =IF(ISBLANK(#REF!),"",CONCATENATE(exp_id,"_",tbl_SeqLib[[#This Row],[Well]])) -> _E1
A8: 6 | B8: =RIGHT(tbl_SeqLib[[#This Row],[Well]],LEN(tbl_SeqLib[[#This Row],[Well]])-1) -> 1 | C8: F1 | H8: 06 | I8: =IF(LEN(tbl_SeqLib[[#This Row],[PCR '[DNA'] (ng / µl)]])>0,1,0) -> 0 | J8: =IF(LEN(tbl_SeqLib[[#This Row],[Sample ID]])>0,1,0) -> 0 | K8: =IF(SUMIF(tbl_SeqLib[Column],tbl_SeqLib[[#This Row],[Column]],tbl_SeqLib[DNA conc present])>0,1,0) -> 0 | L8: =IF(SUM(tbl_SeqLib[[#This Row],[DNA conc present]:[Sample ID present]])>0,1,0) -> 0 | M8: =IF(LEN(tbl_SeqLib[[#This Row],[PCR '[DNA'] (ng / µl)]])=0,"",IF(endrepair_targetmass/tbl_SeqLib[[#This Row],[PCR '[DNA'] (ng / µl)]]>endrepair_maxvol,endrepair_maxvol,ROUNDUP(SUM(endrepair_targetmass/tbl_SeqLib[[#This Row],[PCR '[DNA'] (ng / µl)]]),1))) | N8: =ROUNDDOWN(_xlfn.MAXIFS(tbl_SeqLib[Exact],tbl_SeqLib[Column],tbl_SeqLib[[#This Row],[Column]]),1) -> 0 | O8: =AVERAGE(tbl_SeqLib[Exact]) -> #DIV/0! | P8: =MAX(tbl_SeqLib[Exact]) -> 0 | Q8: =IF(AND(tbl_SeqLib[[#This Row],[Calculate]],LEN(tbl_SeqLib[[#This Row],[PCR product (µl) added (if different from calculated)]])=0),IF(vol_calc=Reference!$E$39,tbl_SeqLib[[#This Row],[Max per plate]],IF(vol_calc=Reference!$E$40,tbl_SeqLib[[#This Row],[Avg per plate]],IF(vol_calc=Reference!$E$38,tbl_SeqLib[[#This Row],[Max for col]],"ERROR"))),"") | S8: =IF(tbl_SeqLib[[#This Row],[Calculate]]=0,"",SUM(endrepair_maxvol-IF(tbl_SeqLib[[#This Row],[PCR product (µl) added (if different from calculated)]]>0,tbl_SeqLib[[#This Row],[PCR product (µl) added (if different from calculated)]],tbl_SeqLib[[#This Row],[PCR product (µl) to add for end-repair (calculated)]]))) | T8: =IF(ISBLANK(#REF!),"",CONCATENATE(exp_id,"_",tbl_SeqLib[[#This Row],[Well]])) -> _F1
A9: 7 | B9: =RIGHT(tbl_SeqLib[[#This Row],[Well]],LEN(tbl_SeqLib[[#This Row],[Well]])-1) -> 1 | C9: G1 | H9: 07 | I9: =IF(LEN(tbl_SeqLib[[#This Row],[PCR '[DNA'] (ng / µl)]])>0,1,0) -> 0 | J9: =IF(LEN(tbl_SeqLib[[#This Row],[Sample ID]])>0,1,0) -> 0 | K9: =IF(SUMIF(tbl_SeqLib[Column],tbl_SeqLib[[#This Row],[Column]],tbl_SeqLib[DNA conc present])>0,1,0) -> 0 | L9: =IF(SUM(tbl_SeqLib[[#This Row],[DNA conc present]:[Sample ID present]])>0,1,0) -> 0 | M9: =IF(LEN(tbl_SeqLib[[#This Row],[PCR '[DNA'] (ng / µl)]])=0,"",IF(endrepair_targetmass/tbl_SeqLib[[#This Row],[PCR '[DNA'] (ng / µl)]]>endrepair_maxvol,endrepair_maxvol,ROUNDUP(SUM(endrepair_targetmass/tbl_SeqLib[[#This Row],[PCR '[DNA'] (ng / µl)]]),1))) | N9: =ROUNDDOWN(_xlfn.MAXIFS(tbl_SeqLib[Exact],tbl_SeqLib[Column],tbl_SeqLib[[#This Row],[Column]]),1) -> 0 | O9: =AVERAGE(tbl_SeqLib[Exact]) -> #DIV/0! | P9: =MAX(tbl_SeqLib[Exact]) -> 0 | Q9: =IF(AND(tbl_SeqLib[[#This Row],[Calculate]],LEN(tbl_SeqLib[[#This Row],[PCR product (µl) added (if different from calculated)]])=0),IF(vol_calc=Reference!$E$39,tbl_SeqLib[[#This Row],[Max per plate]],IF(vol_calc=Reference!$E$40,tbl_SeqLib[[#This Row],[Avg per plate]],IF(vol_calc=Reference!$E$38,tbl_SeqLib[[#This Row],[Max for col]],"ERROR"))),"") | S9: =IF(tbl_SeqLib[[#This Row],[Calculate]]=0,"",SUM(endrepair_maxvol-IF(tbl_SeqLib[[#This Row],[PCR product (µl) added (if different from calculated)]]>0,tbl_SeqLib[[#This Row],[PCR product (µl) added (if different from calculated)]],tbl_SeqLib[[#This Row],[PCR product (µl) to add for end-repair (calculated)]]))) | T9: =IF(ISBLANK(#REF!),"",CONCATENATE(exp_id,"_",tbl_SeqLib[[#This Row],[Well]])) -> _G1
A10: 8 | B10: =RIGHT(tbl_SeqLib[[#This Row],[Well]],LEN(tbl_SeqLib[[#This Row],[Well]])-1) -> 1 | C10: H1 | H10: 08 | I10: =IF(LEN(tbl_SeqLib[[#This Row],[PCR '[DNA'] (ng / µl)]])>0,1,0) -> 0 | J10: =IF(LEN(tbl_SeqLib[[#This Row],[Sample ID]])>0,1,0) -> 0 | K10: =IF(SUMIF(tbl_SeqLib[Column],tbl_SeqLib[[#This Row],[Column]],tbl_SeqLib[DNA conc present])>0,1,0) -> 0 | L10: =IF(SUM(tbl_SeqLib[[#This Row],[DNA conc present]:[Sample ID present]])>0,1,0) -> 0 | M10: =IF(LEN(tbl_SeqLib[[#This Row],[PCR '[DNA'] (ng / µl)]])=0,"",IF(endrepair_targetmass/tbl_SeqLib[[#This Row],[PCR '[DNA'] (ng / µl)]]>endrepair_maxvol,endrepair_maxvol,ROUNDUP(SUM(endrepair_targetmass/tbl_SeqLib[[#This Row],[PCR '[DNA'] (ng / µl)]]),1))) | N10: =ROUNDDOWN(_xlfn.MAXIFS(tbl_SeqLib[Exact],tbl_SeqLib[Column],tbl_SeqLib[[#This Row],[Column]]),1) -> 0 | O10: =AVERAGE(tbl_SeqLib[Exact]) -> #DIV/0! | P10: =MAX(tbl_SeqLib[Exact]) -> 0 | Q10: =IF(AND(tbl_SeqLib[[#This Row],[Calculate]],LEN(tbl_SeqLib[[#This Row],[PCR product (µl) added (if different from calculated)]])=0),IF(vol_calc=Reference!$E$39,tbl_SeqLib[[#This Row],[Max per plate]],IF(vol_calc=Reference!$E$40,tbl_SeqLib[[#This Row],[Avg per plate]],IF(vol_calc=Reference!$E$38,tbl_SeqLib[[#This Row],[Max for col]],"ERROR"))),"") | S10: =IF(tbl_SeqLib[[#This Row],[Calculate]]=0,"",SUM(endrepair_maxvol-IF(tbl_SeqLib[[#This Row],[PCR product (µl) added (if different from calculated)]]>0,tbl_SeqLib[[#This Row],[PCR product (µl) added (if different from calculated)]],tbl_SeqLib[[#This Row],[PCR product (µl) to add for end-repair (calculated)]]))) | T10: =IF(ISBLANK(#REF!),"",CONCATENATE(exp_id,"_",tbl_SeqLib[[#This Row],[Well]])) -> _H1
A11: 9 | B11: =RIGHT(tbl_SeqLib[[#This Row],[Well]],LEN(tbl_SeqLib[[#This Row],[Well]])-1) -> 2 | C11: A2 | H11: 09 | I11: =IF(LEN(tbl_SeqLib[[#This Row],[PCR '[DNA'] (ng / µl)]])>0,1,0) -> 0 | J11: =IF(LEN(tbl_SeqLib[[#This Row],[Sample ID]])>0,1,0) -> 0 | K11: =IF(SUMIF(tbl_SeqLib[Column],tbl_SeqLib[[#This Row],[Column]],tbl_SeqLib[DNA conc present])>0,1,0) -> 0 | L11: =IF(SUM(tbl_SeqLib[[#This Row],[DNA conc present]:[Sample ID present]])>0,1,0) -> 0 | M11: =IF(LEN(tbl_SeqLib[[#This Row],[PCR '[DNA'] (ng / µl)]])=0,"",IF(endrepair_targetmass/tbl_SeqLib[[#This Row],[PCR '[DNA'] (ng / µl)]]>endrepair_maxvol,endrepair_maxvol,ROUNDUP(SUM(endrepair_targetmass/tbl_SeqLib[[#This Row],[PCR '[DNA'] (ng / µl)]]),1))) | N11: =ROUNDDOWN(_xlfn.MAXIFS(tbl_SeqLib[Exact],tbl_SeqLib[Column],tbl_SeqLib[[#This Row],[Column]]),1) -> 0 | O11: =AVERAGE(tbl_SeqLib[Exact]) -> #DIV/0! | P11: =MAX(tbl_SeqLib[Exact]) -> 0 | Q11: =IF(AND(tbl_SeqLib[[#This Row],[Calculate]],LEN(tbl_SeqLib[[#This Row],[PCR product (µl) added (if different from calculated)]])=0),IF(vol_calc=Reference!$E$39,tbl_SeqLib[[#This Row],[Max per plate]],IF(vol_calc=Reference!$E$40,tbl_SeqLib[[#This Row],[Avg per plate]],IF(vol_calc=Reference!$E$38,tbl_SeqLib[[#This Row],[Max for col]],"ERROR"))),"") | S11: =IF(tbl_SeqLib[[#This Row],[Calculate]]=0,"",SUM(endrepair_maxvol-IF(tbl_SeqLib[[#This Row],[PCR product (µl) added (if different from calculated)]]>0,tbl_SeqLib[[#This Row],[PCR product (µl) added (if different from calculated)]],tbl_SeqLib[[#This Row],[PCR product (µl) to add for end-repair (calculated)]]))) | T11: =IF(ISBLANK(#REF!),"",CONCATENATE(exp_id,"_",tbl_SeqLib[[#This Row],[Well]])) -> _A2
A12: 10 | B12: =RIGHT(tbl_SeqLib[[#This Row],[Well]],LEN(tbl_SeqLib[[#This Row],[Well]])-1) -> 2 | C12: B2 | H12: 10 | I12: =IF(LEN(tbl_SeqLib[[#This Row],[PCR '[DNA'] (ng / µl)]])>0,1,0) -> 0 | J12: =IF(LEN(tbl_SeqLib[[#This Row],[Sample ID]])>0,1,0) -> 0 | K12: =IF(SUMIF(tbl_SeqLib[Column],tbl_SeqLib[[#This Row],[Column]],tbl_SeqLib[DNA conc present])>0,1,0) -> 0 | L12: =IF(SUM(tbl_SeqLib[[#This Row],[DNA conc present]:[Sample ID present]])>0,1,0) -> 0 | M12: =IF(LEN(tbl_SeqLib[[#This Row],[PCR '[DNA'] (ng / µl)]])=0,"",IF(endrepair_targetmass/tbl_SeqLib[[#This Row],[PCR '[DNA'] (ng / µl)]]>endrepair_maxvol,endrepair_maxvol,ROUNDUP(SUM(endrepair_targetmass/tbl_SeqLib[[#This Row],[PCR '[DNA'] (ng / µl)]]),1))) | N12: =ROUNDDOWN(_xlfn.MAXIFS(tbl_SeqLib[Exact],tbl_SeqLib[Column],tbl_SeqLib[[#This Row],[Column]]),1) -> 0 | O12: =AVERAGE(tbl_SeqLib[Exact]) -> #DIV/0! | P12: =MAX(tbl_SeqLib[Exact]) -> 0 | Q12: =IF(AND(tbl_SeqLib[[#This Row],[Calculate]],LEN(tbl_SeqLib[[#This Row],[PCR product (µl) added (if different from calculated)]])=0),IF(vol_calc=Reference!$E$39,tbl_SeqLib[[#This Row],[Max per plate]],IF(vol_calc=Reference!$E$40,tbl_SeqLib[[#This Row],[Avg per plate]],IF(vol_calc=Reference!$E$38,tbl_SeqLib[[#This Row],[Max for col]],"ERROR"))),"") | S12: =IF(tbl_SeqLib[[#This Row],[Calculate]]=0,"",SUM(endrepair_maxvol-IF(tbl_SeqLib[[#This Row],[PCR product (µl) added (if different from calculated)]]>0,tbl_SeqLib[[#This Row],[PCR product (µl) added (if different from calculated)]],tbl_SeqLib[[#This Row],[PCR product (µl) to add for end-repair (calculated)]]))) | T12: =IF(ISBLANK(#REF!),"",CONCATENATE(exp_id,"_",tbl_SeqLib[[#This Row],[Well]])) -> _B2
A13: 11 | B13: =RIGHT(tbl_SeqLib[[#This Row],[Well]],LEN(tbl_SeqLib[[#This Row],[Well]])-1) -> 2 | C13: C2 | H13: 11 | I13: =IF(LEN(tbl_SeqLib[[#This Row],[PCR '[DNA'] (ng / µl)]])>0,1,0) -> 0 | J13: =IF(LEN(tbl_SeqLib[[#This Row],[Sample ID]])>0,1,0) -> 0 | K13: =IF(SUMIF(tbl_SeqLib[Column],tbl_SeqLib[[#This Row],[Column]],tbl_SeqLib[DNA conc present])>0,1,0) -> 0 | L13: =IF(SUM(tbl_SeqLib[[#This Row],[DNA conc present]:[Sample ID present]])>0,1,0) -> 0 | M13: =IF(LEN(tbl_SeqLib[[#This Row],[PCR '[DNA'] (ng / µl)]])=0,"",IF(endrepair_targetmass/tbl_SeqLib[[#This Row],[PCR '[DNA'] (ng / µl)]]>endrepair_maxvol,endrepair_maxvol,ROUNDUP(SUM(endrepair_targetmass/tbl_SeqLib[[#This Row],[PCR '[DNA'] (ng / µl)]]),1))) | N13: =ROUNDDOWN(_xlfn.MAXIFS(tbl_SeqLib[Exact],tbl_SeqLib[Column],tbl_SeqLib[[#This Row],[Column]]),1) -> 0 | O13: =AVERAGE(tbl_SeqLib[Exact]) -> #DIV/0! | P13: =MAX(tbl_SeqLib[Exact]) -> 0 | Q13: =IF(AND(tbl_SeqLib[[#This Row],[Calculate]],LEN(tbl_SeqLib[[#This Row],[PCR product (µl) added (if different from calculated)]])=0),IF(vol_calc=Reference!$E$39,tbl_SeqLib[[#This Row],[Max per plate]],IF(vol_calc=Reference!$E$40,tbl_SeqLib[[#This Row],[Avg per plate]],IF(vol_calc=Reference!$E$38,tbl_SeqLib[[#This Row],[Max for col]],"ERROR"))),"") | S13: =IF(tbl_SeqLib[[#This Row],[Calculate]]=0,"",SUM(endrepair_maxvol-IF(tbl_SeqLib[[#This Row],[PCR product (µl) added (if different from calculated)]]>0,tbl_SeqLib[[#This Row],[PCR product (µl) added (if different from calculated)]],tbl_SeqLib[[#This Row],[PCR product (µl) to add for end-repair (calculated)]]))) | T13: =IF(ISBLANK(#REF!),"",CONCATENATE(exp_id,"_",tbl_SeqLib[[#This Row],[Well]])) -> _C2
A14: 12 | B14: =RIGHT(tbl_SeqLib[[#This Row],[Well]],LEN(tbl_SeqLib[[#This Row],[Well]])-1) -> 2 | C14: D2 | H14: 12 | I14: =IF(LEN(tbl_SeqLib[[#This Row],[PCR '[DNA'] (ng / µl)]])>0,1,0) -> 0 | J14: =IF(LEN(tbl_SeqLib[[#This Row],[Sample ID]])>0,1,0) -> 0 | K14: =IF(SUMIF(tbl_SeqLib[Column],tbl_SeqLib[[#This Row],[Column]],tbl_SeqLib[DNA conc present])>0,1,0) -> 0 | L14: =IF(SUM(tbl_SeqLib[[#This Row],[DNA conc present]:[Sample ID present]])>0,1,0) -> 0 | M14: =IF(LEN(tbl_SeqLib[[#This Row],[PCR '[DNA'] (ng / µl)]])=0,"",IF(endrepair_targetmass/tbl_SeqLib[[#This Row],[PCR '[DNA'] (ng / µl)]]>endrepair_maxvol,endrepair_maxvol,ROUNDUP(SUM(endrepair_targetmass/tbl_SeqLib[[#This Row],[PCR '[DNA'] (ng / µl)]]),1))) | N14: =ROUNDDOWN(_xlfn.MAXIFS(tbl_SeqLib[Exact],tbl_SeqLib[Column],tbl_SeqLib[[#This Row],[Column]]),1) -> 0 | O14: =AVERAGE(tbl_SeqLib[Exact]) -> #DIV/0! | P14: =MAX(tbl_SeqLib[Exact]) -> 0 | Q14: =IF(AND(tbl_SeqLib[[#This Row],[Calculate]],LEN(tbl_SeqLib[[#This Row],[PCR product (µl) added (if different from calculated)]])=0),IF(vol_calc=Reference!$E$39,tbl_SeqLib[[#This Row],[Max per plate]],IF(vol_calc=Reference!$E$40,tbl_SeqLib[[#This Row],[Avg per plate]],IF(vol_calc=Reference!$E$38,tbl_SeqLib[[#This Row],[Max for col]],"ERROR"))),"") | S14: =IF(tbl_SeqLib[[#This Row],[Calculate]]=0,"",SUM(endrepair_maxvol-IF(tbl_SeqLib[[#This Row],[PCR product (µl) added (if different from calculated)]]>0,tbl_SeqLib[[#This Row],[PCR product (µl) added (if different from calculated)]],tbl_SeqLib[[#This Row],[PCR product (µl) to add for end-repair (calculated)]]))) | T14: =IF(ISBLANK(#REF!),"",CONCATENATE(exp_id,"_",tbl_SeqLib[[#This Row],[Well]])) -> _D2
... A98: 96 | B98: =RIGHT(tbl_SeqLib[[#This Row],[Well]],LEN(tbl_SeqLib[[#This Row],[Well]])-1) -> 12 | C98: H12 | H98: 96 | I98: =IF(LEN(tbl_SeqLib[[#This Row],[PCR '[DNA'] (ng / µl)]])>0,1,0) -> 0 | J98: =IF(LEN(tbl_SeqLib[[#This Row],[Sample ID]])>0,1,0) -> 0 | K98: =IF(SUMIF(tbl_SeqLib[Column],tbl_SeqLib[[#This Row],[Column]],tbl_SeqLib[DNA conc present])>0,1,0) -> 0 | L98: =IF(SUM(tbl_SeqLib[[#This Row],[DNA conc present]:[Sample ID present]])>0,1,0) -> 0 | M98: =IF(LEN(tbl_SeqLib[[#This Row],[PCR '[DNA'] (ng / µl)]])=0,"",IF(endrepair_targetmass/tbl_SeqLib[[#This Row],[PCR '[DNA'] (ng / µl)]]>endrepair_maxvol,endrepair_maxvol,ROUNDUP(SUM(endrepair_targetmass/tbl_SeqLib[[#This Row],[PCR '[DNA'] (ng / µl)]]),1))) | N98: =ROUNDDOWN(_xlfn.MAXIFS(tbl_SeqLib[Exact],tbl_SeqLib[Column],tbl_SeqLib[[#This Row],[Column]]),1) -> 0 | O98: =AVERAGE(tbl_SeqLib[Exact]) -> #DIV/0! | P98: =MAX(tbl_SeqLib[Exact]) -> 0 | Q98: =IF(AND(tbl_SeqLib[[#This Row],[Calculate]],LEN(tbl_SeqLib[[#This Row],[PCR product (µl) added (if different from calculated)]])=0),IF(vol_calc=Reference!$E$39,tbl_SeqLib[[#This Row],[Max per plate]],IF(vol_calc=Reference!$E$40,tbl_SeqLib[[#This Row],[Avg per plate]],IF(vol_calc=Reference!$E$38,tbl_SeqLib[[#This Row],[Max for col]],"ERROR"))),"") | S98: =IF(tbl_SeqLib[[#This Row],[Calculate]]=0,"",SUM(endrepair_maxvol-IF(tbl_SeqLib[[#This Row],[PCR product (µl) added (if different from calculated)]]>0,tbl_SeqLib[[#This Row],[PCR product (µl) added (if different from calculated)]],tbl_SeqLib[[#This Row],[PCR product (µl) to add for end-repair (calculated)]]))) | T98: =IF(ISBLANK(#REF!),"",CONCATENATE(exp_id,"_",tbl_SeqLib[[#This Row],[Well]])) -> _H12

Sheet Reference
A1: Instructions
A2: This template is to be used to record library prep and sequencing steps as part of a NOMADS sequencing run.
A3: To prevent inadvertent loss of data, cells are protected from editing. You can only select unlocked cells. Use tab to navigate
A5: Process
A6: 1. Enter all details into the 'Assay' (experiment level) and 'Library' (reaction level) tabs, ensuring all yellow highlighted cells are complete
A7: - when copying from another worksheet, always right-click and paste VALUES:
A8: 2. Save workbook with the correct filename to the shared Google Drive folder
A14: Reference values (change only if required)
A15: Assumptions | E15: Look-ups
A16: Description | E16: Flow cell status
A17: End repair max volume | B17: 10 | C17: ul | E17: New
A18: Adapter ligation max volume | B18: =IF(adaptlig_rxn_vol=100,65,30) -> 30 | C18: ul | E18: Used
A19: Flow cell load max volume | B19: 12 | C19: ul
A20: Minimum final pooled [DNA] | B20: =ROUND(SUM(flowcell_targetmass/flowcell_maxvol),0) -> 67 | C20: ng/ul | E20: Adaptor ligation rxn vol
A21: Post-PCR clean-up target [DNA] | B21: 30 | C21: ng/ul | E21: 100
A22: End-repair vol calculation type | B22: 1 per column (max) | C22: (recommend 1 per column) | E22: 50
A23: Missing quantification | B23: column average | C23: (recommend plate average)
E24: ONT Platforms
A25: Experiment | E25: Mk1b
A26: type | B26: seqlib | E26: Mk1c
A27: sub-type | B27: ligation | E27: Mk1d
A28: version | B28: 11 | E28: GridIon
E29: Promethion
A30: Changelog from prev version | E30: P2
E32: Flow Chemistry
E33: R10.4.1
E36: Volume Calculation Types
E37: Name | F37: Description
E38: 1 per column (max) | F38: max volume per column
E39: Max per plate | F39: max per plate
E40: Avg Per plate | F40: avg per plate
E42: Volume Calculation Types
E43: Name | F43: Description
E44: column average | F44: avg of quantifications in the same column
E45: plate average | F45: avg of quantifications across plate
E47: Wash Volume (ul) | F47: Applies to
E48: 700 | F48: Ento
E49: 200 | F49: Plasmo
E51: Resuspension Vol (ul) | F51: Applies to
E52: 35 | F52: Ento
...

Sheet expt_metadata
A1: expt_id | B1: expt_date | C1: expt_user | D1: expt_type | E1: expt_sub-type | F1: expt_version | G1: expt_notes | H1: expt_summary | I1: expt_rxns | J1: endrepair_targetmass_ng | K1: endrepair_dnaconc_ngul | L1: adaptlig_targetmass_ng | M1: library_dnaconc_ngul | N1: flowcell_checkpores
A2: =IF(LEN(exp_id)=0,"",exp_id) | B2: =IF(LEN(exp_date)=0,"",exp_date) | C2: =IF(LEN(user_name)=0,"",user_name) | D2: =IF(LEN(exp_type)=0,"",exp_type) -> seqlib | E2: =exp_subtype -> ligation | F2: =IF(LEN(exp_version)=0,"",exp_version) -> 11 | G2: =IF(LEN(exp_notes)=0,"",exp_notes) | H2: =IF(LEN(exp_summary)=0,"",exp_summary) | I2: =IF(LEN(exp_rxns)=0,"",exp_rxns) -> 0 | J2: =IF(LEN(endrepair_targetmass)=0,"",endrepair_targetmass) -> 800 | K2: =IF(DNAconc_pooled=0,"",DNAconc_pooled) | L2: =IF(adaptlig_targetmass=0,"",adaptlig_targetmass) | M2: =IF(DNAconc_library=0,"",DNAconc_library) | N2: =IF(LEN(flowcell_checkpores)=0,"",flowcell_checkpores)

Sheet rxn_metadata
A1: sample_id | B1: extraction_id | C1: sample_type | D1: barcode | E1: endrepair_vol_ul
A2: =IF(LEN(Library!D3)=0,"",Library!D3) | B2: =IF(LEN(Library!E3)=0,"",Library!E3) | C2: =IF(LEN(Library!F3)=0,"",Library!F3) | D2: =IF(LEN(Library!D3)=0,"",CONCATENATE("barcode",Library!H3)) | E2: =IF(LEN(Library!Q3)=0,"",IF(Library!R3>0,Library!R3,Library!Q3))
A3: =IF(LEN(Library!D4)=0,"",Library!D4) | B3: =IF(LEN(Library!E4)=0,"",Library!E4) | C3: =IF(LEN(Library!F4)=0,"",Library!F4) | D3: =IF(LEN(Library!D4)=0,"",CONCATENATE("barcode",Library!H4)) | E3: =IF(LEN(Library!Q4)=0,"",IF(Library!R4>0,Library!R4,Library!Q4))
A4: =IF(LEN(Library!D5)=0,"",Library!D5) | B4: =IF(LEN(Library!E5)=0,"",Library!E5) | C4: =IF(LEN(Library!F5)=0,"",Library!F5) | D4: =IF(LEN(Library!D5)=0,"",CONCATENATE("barcode",Library!H5)) | E4: =IF(LEN(Library!Q5)=0,"",IF(Library!R5>0,Library!R5,Library!Q5))
A5: =IF(LEN(Library!D6)=0,"",Library!D6) | B5: =IF(LEN(Library!E6)=0,"",Library!E6) | C5: =IF(LEN(Library!F6)=0,"",Library!F6) | D5: =IF(LEN(Library!D6)=0,"",CONCATENATE("barcode",Library!H6)) | E5: =IF(LEN(Library!Q6)=0,"",IF(Library!R6>0,Library!R6,Library!Q6))
A6: =IF(LEN(Library!D7)=0,"",Library!D7) | B6: =IF(LEN(Library!E7)=0,"",Library!E7) | C6: =IF(LEN(Library!F7)=0,"",Library!F7) | D6: =IF(LEN(Library!D7)=0,"",CONCATENATE("barcode",Library!H7)) | E6: =IF(LEN(Library!Q7)=0,"",IF(Library!R7>0,Library!R7,Library!Q7))
A7: =IF(LEN(Library!D8)=0,"",Library!D8) | B7: =IF(LEN(Library!E8)=0,"",Library!E8) | C7: =IF(LEN(Library!F8)=0,"",Library!F8) | D7: =IF(LEN(Library!D8)=0,"",CONCATENATE("barcode",Library!H8)) | E7: =IF(LEN(Library!Q8)=0,"",IF(Library!R8>0,Library!R8,Library!Q8))
A8: =IF(LEN(Library!D9)=0,"",Library!D9) | B8: =IF(LEN(Library!E9)=0,"",Library!E9) | C8: =IF(LEN(Library!F9)=0,"",Library!F9) | D8: =IF(LEN(Library!D9)=0,"",CONCATENATE("barcode",Library!H9)) | E8: =IF(LEN(Library!Q9)=0,"",IF(Library!R9>0,Library!R9,Library!Q9))
A9: =IF(LEN(Library!D10)=0,"",Library!D10) | B9: =IF(LEN(Library!E10)=0,"",Library!E10) | C9: =IF(LEN(Library!F10)=0,"",Library!F10) | D9: =IF(LEN(Library!D10)=0,"",CONCATENATE("barcode",Library!H10)) | E9: =IF(LEN(Library!Q10)=0,"",IF(Library!R10>0,Library!R10,Library!Q10))
A10: =IF(LEN(Library!D11)=0,"",Library!D11) | B10: =IF(LEN(Library!E11)=0,"",Library!E11) | C10: =IF(LEN(Library!F11)=0,"",Library!F11) | D10: =IF(LEN(Library!D11)=0,"",CONCATENATE("barcode",Library!H11)) | E10: =IF(LEN(Library!Q11)=0,"",IF(Library!R11>0,Library!R11,Library!Q11))
A11: =IF(LEN(Library!D12)=0,"",Library!D12) | B11: =IF(LEN(Library!E12)=0,"",Library!E12) | C11: =IF(LEN(Library!F12)=0,"",Library!F12) | D11: =IF(LEN(Library!D12)=0,"",CONCATENATE("barcode",Library!H12)) | E11: =IF(LEN(Library!Q12)=0,"",IF(Library!R12>0,Library!R12,Library!Q12))
A12: =IF(LEN(Library!D13)=0,"",Library!D13) | B12: =IF(LEN(Library!E13)=0,"",Library!E13) | C12: =IF(LEN(Library!F13)=0,"",Library!F13) | D12: =IF(LEN(Library!D13)=0,"",CONCATENATE("barcode",Library!H13)) | E12: =IF(LEN(Library!Q13)=0,"",IF(Library!R13>0,Library!R13,Library!Q13))
A13: =IF(LEN(Library!D14)=0,"",Library!D14) | B13: =IF(LEN(Library!E14)=0,"",Library!E14) | C13: =IF(LEN(Library!F14)=0,"",Library!F14) | D13: =IF(LEN(Library!D14)=0,"",CONCATENATE("barcode",Library!H14)) | E13: =IF(LEN(Library!Q14)=0,"",IF(Library!R14>0,Library!R14,Library!Q14))
... A97: =IF(LEN(Library!D98)=0,"",Library!D98) | B97: =IF(LEN(Library!E98)=0,"",Library!E98) | C97: =IF(LEN(Library!F98)=0,"",Library!F98) | D97: =IF(LEN(Library!D98)=0,"",CONCATENATE("barcode",Library!H98)) | E97: =IF(LEN(Library!Q98)=0,"",IF(Library!R98>0,Library!R98,Library!Q98))
