Workbook
Name exp_date: Assay!$C$2
Name exp_id: Assay!$C$7
Name exp_notes: Assay!$C$13
Name exp_rxns: Assay!$C$10
Name exp_summary: Assay!$C$6
Name exp_type: Reference!$B$21
Name exp_version: Reference!$B$22
Name export_folder: Reference!$A$25
Name expt_summary: Assay!$C$6
Name expt_type: Reference!$B$21
Name swga_enzyme: Assay!$C$11
Name swga_notes: Assay!$C$13
Name swga_rxnvol: Assay!$C$12
Name swga_targetmass: Reference!$B$17
Name swga_template_maxvol: Reference!$B$18
Name user_initials: Assay!$C$4
Name user_name: Assay!$C$3

Sheet Assay
A1: NOMADS sWGA Worksheet
A2: Date: | G2: (YYYY-MM-DD) | K2: KEY
A3: User: | G3: (enter name) | K3: Required fields
A4: User Initials: | C4: {=IF(ISBLANK(user_name),"",_xlfn.CONCAT(LEFT(_xlfn.TEXTSPLIT(TRIM(user_name)," "),1)))} | G4: (first last) | K4: Calculated fields
A5: Exp Number: | G5: (three digit ID created by the user) | K5: Do NOT use any commas
A6: Exp Summary: | G6: (enter human readable detail)
A7: Exp ID: | C7: =IF(OR(ISBLANK(C3),ISBLANK(C5)),"",CONCATENATE("SW",user_initials,C5)) | G7: (SW = sWGA)
A8: Exp Name: | C8: =IF(OR(ISBLANK(C2),ISBLANK(C3),LEN(C7)=0),"",CONCATENATE(C2,"_",C7))
A9: Filename: | C9: =IF(LEN(C8)=0,"",CONCATENATE(C8,"_",exp_summary))
A10: Number of samples: | C10: =COUNTA(sWGA!E4:E99) -> 0 | G10: (calculated from sWGA tab)
A11: sWGA enzyme | C11: equiphi29 | G11: (select from dropdown)
B12: Reaction Volume: | C12: =IF(swga_enzyme=Reference!$E$17,50,20) -> 20
B13: Notes:
A16: 1 - SWGA | C16: Overage | D16: 0.1
A17: =CONCATENATE(" 1. Make up master mix as below and add ", SUM(D19:D24), " µl to each well") -> 1. Make up master mix as below and add 7.2 µl to each well
A18: Item | D18: Per tube (µl) | F18: =CONCATENATE("MM x",exp_rxns," (µl)") -> MM x0 (µl) | J18: Temperature (oC) | L18: Time (min)
A19: 10x Buffer | D19: =swga_rxnvol/10 -> 2 | F19: =IF(ISBLANK(swga_rxnvol),"",SUM(D19*exp_rxns*(1+$D$16))) -> 0 | J19: =Reference!E26 -> 45 | L19: =Reference!F26 -> Prepare
A20: =IF(swga_enzyme=Reference!$E$17,"100nM Primer Mix","500uM Primer Mix") -> 500uM Primer Mix | D20: =IF(swga_enzyme=Reference!$E$17,0.25,2) -> 2 | F20: =IF(ISBLANK(swga_rxnvol),"",SUM(D20*exp_rxns*(1+$D$16))) -> 0 | J20: =Reference!E27 -> 45 | L20: =Reference!F27 -> 60 min
A21: =IF(swga_enzyme=Reference!$E$17,"BSA (20mg/mL)","DTT") -> DTT | D21: =IF(swga_enzyme=Reference!$E$17,1.25,0.2) -> 0.2 | F21: =IF(ISBLANK(swga_rxnvol),"",SUM(D21*exp_rxns*(1+$D$16))) -> 0 | J21: =Reference!E28 -> 65 | L21: =Reference!F28 -> 10 min
A22: 10mM dNTP | D22: =IF(swga_enzyme=Reference!$E$17,5,2) -> 2 | F22: =IF(ISBLANK(swga_rxnvol),"",SUM(D22*exp_rxns*(1+$D$16))) -> 0 | J22: =Reference!E29 -> 8 | L22: =Reference!F29 -> ∞
A23: =_xlfn.CONCAT(IF(C11="","Select",C11)," polymerase") -> equiphi29 polymerase | D23: 1 | F23: =IF(ISBLANK(swga_rxnvol),"",SUM(D23*exp_rxns*(1+$D$16))) -> 0 | J23: =Reference!E30 -> - | L23: =Reference!F30 -> -
A24: Nuclease-Free H20 | D24: =SUM(swga_rxnvol-swga_template_maxvol)-SUM(D19:E23) -> 0 | F24: =IF(ISBLANK(swga_rxnvol),"",SUM(D24*exp_rxns*(1+$D$16))) -> 0 | J24: =Reference!E31 -> - | L24: =Reference!F31 -> -
G25: =CONCATENATE("Add ",SUM(D19:D24)," µl of MM to each well") -> Add 7.2 µl of MM to each well | J25: =Reference!E32 -> - | L25: =Reference!F32 -> -
J26: =Reference!E33 -> - | L26: =Reference!F33 -> -
A27: =CONCATENATE(" 2. For each sample add target of ",swga_targetmass," ng of DNA for each up to a max vol of ",swga_template_maxvol,"ul. Add TE as required.") -> 2. For each sample add target of 40 ng of DNA for each up to a max vol of 12.8ul. Add TE as required. | K27: (Enter in sWGA Tab)
A28: 3. Run sWGA on thermocycler according to above right table
A29: =IF(swga_enzyme=Reference!$E$17," 4. Quantify 1 µl (199 µl WS 1X HS DNA). Dilute in water if required"," 4. Dilute sWGA product by adding 160 µl water or low TE-Buffer (mix well). Aliquot 90 µl into backup plate and store at 4°C") -> 4. Dilute sWGA product by adding 160 µl water or low TE-Buffer (mix well). Aliquot 90 µl into backup plate and store at 4°C | K29: =IF(swga_enzyme=Reference!$E$17,"(Enter in sWGA Tab)","")
A30: =IF(swga_enzyme=Reference!$E$17, ""," 5. Quantify 1 µl (199 µl WS 1X HS DNA). Dilute in water if required") -> 5. Quantify 1 µl (199 µl WS 1X HS DNA). Dilute in water if required | K30: =IF(swga_enzyme=Reference!$E$17,"","(Enter in sWGA Tab)") -> (Enter in sWGA Tab)
A32: sWGA | B32: Select ID to reference in platemap: | F32: Sample ID
B33: 1 | C33: 2 | D33: 3 | E33: 4 | F33: 5 | G33: 6 | H33: 7 | I33: 8 | J33: 9 | K33: 10 | L33: 11 | M33: 12
A34: A | B34: =sWGA!$D4 | C34: =sWGA!$D12 | D34: =sWGA!$D20 | E34: =sWGA!$D28 | F34: =sWGA!$D36 | G34: =sWGA!$D44 | H34: =sWGA!$D52 | I34: =sWGA!$D60 | J34: =sWGA!$D68 | K34: =sWGA!$D76 | L34: =sWGA!$D84 | M34: =sWGA!$D92
A35: B | B35: =sWGA!$D5 | C35: =sWGA!$D13 | D35: =sWGA!$D21 | E35: =sWGA!$D29 | F35: =sWGA!$D37 | G35: =sWGA!$D45 | H35: =sWGA!$D53 | I35: =sWGA!$D61 | J35: =sWGA!$D69 | K35: =sWGA!$D77 | L35: =sWGA!$D85 | M35: =sWGA!$D93
A36: C | B36: =sWGA!$D6 | C36: =sWGA!$D14 | D36: =sWGA!$D22 | E36: =sWGA!$D30 | F36: =sWGA!$D38 | G36: =sWGA!$D46 | H36: =sWGA!$D54 | I36: =sWGA!$D62 | J36: =sWGA!$D70 | K36: =sWGA!$D78 | L36: =sWGA!$D86 | M36: =sWGA!$D94
A37: D | B37: =sWGA!$D7 | C37: =sWGA!$D15 | D37: =sWGA!$D23 | E37: =sWGA!$D31 | F37: =sWGA!$D39 | G37: =sWGA!$D47 | H37: =sWGA!$D55 | I37: =sWGA!$D63 | J37: =sWGA!$D71 | K37: =sWGA!$D79 | L37: =sWGA!$D87 | M37: =sWGA!$D95
A38: E | B38: =sWGA!$D8 | C38: =sWGA!$D16 | D38: =sWGA!$D24 | E38: =sWGA!$D32 | F38: =sWGA!$D40 | G38: =sWGA!$D48 | H38: =sWGA!$D56 | I38: =sWGA!$D64 | J38: =sWGA!$D72 | K38: =sWGA!$D80 | L38: =sWGA!$D88 | M38: =sWGA!$D96
A39: F | B39: =sWGA!$D9 | C39: =sWGA!$D17 | D39: =sWGA!$D25 | E39: =sWGA!$D33 | F39: =sWGA!$D41 | G39: =sWGA!$D49 | H39: =sWGA!$D57 | I39: =sWGA!$D65 | J39: =sWGA!$D73 | K39: =sWGA!$D81 | L39: =sWGA!$D89 | M39: =sWGA!$D97
A40: G | B40: =sWGA!$D10 | C40: =sWGA!$D18 | D40: =sWGA!$D26 | E40: =sWGA!$D34 | F40: =sWGA!$D42 | G40: =sWGA!$D50 | H40: =sWGA!$D58 | I40: =sWGA!$D66 | J40: =sWGA!$D74 | K40: =sWGA!$D82 | L40: =sWGA!$D90 | M40: =sWGA!$D98
A41: H | B41: =sWGA!$D11 | C41: =sWGA!$D19 | D41: =sWGA!$D27 | E41: =sWGA!$D35 | F41: =sWGA!$D43 | G41: =sWGA!$D51 | H41: =sWGA!$D59 | I41: =sWGA!$D67 | J41: =sWGA!$D75 | K41: =sWGA!$D83 | L41: =sWGA!$D91 | M41: =sWGA!$D99

Sheet sWGA
E1: Copy these columns to the PCR template
D2: Sample Information
A3: # | B3: Column | C3: Well | D3: Platemap ID | E3: Sample ID | F3: Extraction ID | G3: Sample Type | H3: sWGA template (ul) | I3: sWGA qubit [DNA] (ng / ul) | J3: sWGA Dilution Factor | K3: sWGA product [DNA] (ng / ul)
A4: 1 | B4: =RIGHT(tbl_sWGA[[#This Row],[Well]],LEN(tbl_sWGA[[#This Row],[Well]])-1) -> 1 | C4: A1 | D4: =IF(Assay!$F$32=Reference!$E$56,IF(LEN(tbl_sWGA[[#This Row],[Sample ID]])>0,tbl_sWGA[[#This Row],[Sample ID]],""),IF(LEN(tbl_sWGA[[#This Row],[Extraction ID]])>0,tbl_sWGA[[#This Row],[Extraction ID]],"")) | K4: =IF(OR(ISBLANK(tbl_sWGA[[#This Row],[sWGA qubit '[DNA'] (ng / ul)]]),ISBLANK(tbl_sWGA[[#This Row],[sWGA Dilution Factor]])),"",SUM(tbl_sWGA[[#This Row],[sWGA qubit '[DNA'] (ng / ul)]]*tbl_sWGA[[#This Row],[sWGA Dilution Factor]]))
A5: 2 | B5: =RIGHT(tbl_sWGA[[#This Row],[Well]],LEN(tbl_sWGA[[#This Row],[Well]])-1) -> 1 | C5: B1 | D5: =IF(Assay!$F$32=Reference!$E$56,IF(LEN(tbl_sWGA[[#This Row],[Sample ID]])>0,tbl_sWGA[[#This Row],[Sample ID]],""),IF(LEN(tbl_sWGA[[#This Row],[Extraction ID]])>0,tbl_sWGA[[#This Row],[Extraction ID]],"")) | K5: =IF(OR(ISBLANK(tbl_sWGA[[#This Row],[sWGA qubit '[DNA'] (ng / ul)]]),ISBLANK(tbl_sWGA[[#This Row],[sWGA Dilution Factor]])),"",SUM(tbl_sWGA[[#This Row],[sWGA qubit '[DNA'] (ng / ul)]]*tbl_sWGA[[#This Row],[sWGA Dilution Factor]]))
A6: 3 | B6: =RIGHT(tbl_sWGA[[#This Row],[Well]],LEN(tbl_sWGA[[#This Row],[Well]])-1) -> 1 | C6: C1 | D6: =IF(Assay!$F$32=Reference!$E$56,IF(LEN(tbl_sWGA[[#This Row],[Sample ID]])>0,tbl_sWGA[[#This Row],[Sample ID]],""),IF(LEN(tbl_sWGA[[#This Row],[Extraction ID]])>0,tbl_sWGA[[#This Row],[Extraction ID]],"")) | K6: =IF(OR(ISBLANK(tbl_sWGA[[#This Row],[sWGA qubit '[DNA'] (ng / ul)]]),ISBLANK(tbl_sWGA[[#This Row],[sWGA Dilution Factor]])),"",SUM(tbl_sWGA[[#This Row],[sWGA qubit '[DNA'] (ng / ul)]]*tbl_sWGA[[#This Row],[sWGA Dilution Factor]]))
A7: 4 | B7: =RIGHT(tbl_sWGA[[#This Row],[Well]],LEN(tbl_sWGA[[#This Row],[Well]])-1) -> 1 | C7: D1 | D7: =IF(Assay!$F$32=Reference!$E$56,IF(LEN(tbl_sWGA[[#This Row],[Sample ID]])>0,tbl_sWGA[[#This Row],[Sample ID]],""),IF(LEN(tbl_sWGA[[#This Row],[Extraction ID]])>0,tbl_sWGA[[#This Row],[Extraction ID]],"")) | K7: =IF(OR(ISBLANK(tbl_sWGA[[#This Row],[sWGA qubit '[DNA'] (ng / ul)]]),ISBLANK(tbl_sWGA[[#This Row],[sWGA Dilution Factor]])),"",SUM(tbl_sWGA[[#This Row],[sWGA qubit '[DNA'] (ng / ul)]]*tbl_sWGA[[#This Row],[sWGA Dilution Factor]]))
A8: 5 | B8: =RIGHT(tbl_sWGA[[#This Row],[Well]],LEN(tbl_sWGA[[#This Row],[Well]])-1) -> 1 | C8: E1 | D8: =IF(Assay!$F$32=Reference!$E$56,IF(LEN(tbl_sWGA[[#This Row],[Sample ID]])>0,tbl_sWGA[[#This Row],[Sample ID]],""),IF(LEN(tbl_sWGA[[#This Row],[Extraction ID]])>0,tbl_sWGA[[#This Row],[Extraction ID]],"")) | K8: =IF(OR(ISBLANK(tbl_sWGA[[#This Row],[sWGA qubit '[DNA'] (ng / ul)]]),ISBLANK(tbl_sWGA[[#This Row],[sWGA Dilution Factor]])),"",SUM(tbl_sWGA[[#This Row],[sWGA qubit '[DNA'] (ng / ul)]]*tbl_sWGA[[#This Row],[sWGA Dilution Factor]]))
A9: 6 | B9: =RIGHT(tbl_sWGA[[#This Row],[Well]],LEN(tbl_sWGA[[#This Row],[Well]])-1) -> 1 | C9: F1 | D9: =IF(Assay!$F$32=Reference!$E$56,IF(LEN(tbl_sWGA[[#This Row],[Sample ID]])>0,tbl_sWGA[[#This Row],[Sample ID]],""),IF(LEN(tbl_sWGA[[#This Row],[Extraction ID]])>0,tbl_sWGA[[#This Row],[Extraction ID]],"")) | K9: =IF(OR(ISBLANK(tbl_sWGA[[#This Row],[sWGA qubit '[DNA'] (ng / ul)]]),ISBLANK(tbl_sWGA[[#This Row],[sWGA Dilution Factor]])),"",SUM(tbl_sWGA[[#This Row],[sWGA qubit '[DNA'] (ng / ul)]]*tbl_sWGA[[#This Row],[sWGA Dilution Factor]]))
A10: 7 | B10: =RIGHT(tbl_sWGA[[#This Row],[Well]],LEN(tbl_sWGA[[#This Row],[Well]])-1) -> 1 | C10: G1 | D10: =IF(Assay!$F$32=Reference!$E$56,IF(LEN(tbl_sWGA[[#This Row],[Sample ID]])>0,tbl_sWGA[[#This Row],[Sample ID]],""),IF(LEN(tbl_sWGA[[#This Row],[Extraction ID]])>0,tbl_sWGA[[#This Row],[Extraction ID]],"")) | K10: =IF(OR(ISBLANK(tbl_sWGA[[#This Row],[sWGA qubit '[DNA'] (ng / ul)]]),ISBLANK(tbl_sWGA[[#This Row],[sWGA Dilution Factor]])),"",SUM(tbl_sWGA[[#This Row],[sWGA qubit '[DNA'] (ng / ul)]]*tbl_sWGA[[#This Row],[sWGA Dilution Factor]]))
A11: 8 | B11: =RIGHT(tbl_sWGA[[#This Row],[Well]],LEN(tbl_sWGA[[#This Row],[Well]])-1) -> 1 | C11: H1 | D11: =IF(Assay!$F$32=Reference!$E$56,IF(LEN(tbl_sWGA[[#This Row],[Sample ID]])>0,tbl_sWGA[[#This Row],[Sample ID]],""),IF(LEN(tbl_sWGA[[#This Row],[Extraction ID]])>0,tbl_sWGA[[#This Row],[Extraction ID]],"")) | K11: =IF(OR(ISBLANK(tbl_sWGA[[#This Row],[sWGA qubit '[DNA'] (ng / ul)]]),ISBLANK(tbl_sWGA[[#This Row],[sWGA Dilution Factor]])),"",SUM(tbl_sWGA[[#This Row],[sWGA qubit '[DNA'] (ng / ul)]]*tbl_sWGA[[#This Row],[sWGA Dilution Factor]]))
A12: 9 | B12: =RIGHT(tbl_sWGA[[#This Row],[Well]],LEN(tbl_sWGA[[#This Row],[Well]])-1) -> 2 | C12: A2 | D12: =IF(Assay!$F$32=Reference!$E$56,IF(LEN(tbl_sWGA[[#This Row],[Sample ID]])>0,tbl_sWGA[[#This Row],[Sample ID]],""),IF(LEN(tbl_sWGA[[#This Row],[Extraction ID]])>0,tbl_sWGA[[#This Row],[Extraction ID]],"")) | K12: =IF(OR(ISBLANK(tbl_sWGA[[#This Row],[sWGA qubit '[DNA'] (ng / ul)]]),ISBLANK(tbl_sWGA[[#This Row],[sWGA Dilution Factor]])),"",SUM(tbl_sWGA[[#This Row],[sWGA qubit '[DNA'] (ng / ul)]]*tbl_sWGA[[#This Row],[sWGA Dilution Factor]]))
A13: 10 | B13: =RIGHT(tbl_sWGA[[#This Row],[Well]],LEN(tbl_sWGA[[#This Row],[Well]])-1) -> 2 | C13: B2 | D13: =IF(Assay!$F$32=Reference!$E$56,IF(LEN(tbl_sWGA[[#This Row],[Sample ID]])>0,tbl_sWGA[[#This Row],[Sample ID]],""),IF(LEN(tbl_sWGA[[#This Row],[Extraction ID]])>0,tbl_sWGA[[#This Row],[Extraction ID]],"")) | K13: =IF(OR(ISBLANK(tbl_sWGA[[#This Row],[sWGA qubit '[DNA'] (ng / ul)]]),ISBLANK(tbl_sWGA[[#This Row],[sWGA Dilution Factor]])),"",SUM(tbl_sWGA[[#This Row],[sWGA qubit '[DNA'] (ng / ul)]]*tbl_sWGA[[#This Row],[sWGA Dilution Factor]]))
A14: 11 | B14: =RIGHT(tbl_sWGA[[#This Row],[Well]],LEN(tbl_sWGA[[#This Row],[Well]])-1) -> 2 | C14: C2 | D14: =IF(Assay!$F$32=Reference!$E$56,IF(LEN(tbl_sWGA[[#This Row],[Sample ID]])>0,tbl_sWGA[[#This Row],[Sample ID]],""),IF(LEN(tbl_sWGA[[#This Row],[Extraction ID]])>0,tbl_sWGA[[#This Row],[Extraction ID]],"")) | K14: =IF(OR(ISBLANK(tbl_sWGA[[#This Row],[sWGA qubit '[DNA'] (ng / ul)]]),ISBLANK(tbl_sWGA[[#This Row],[sWGA Dilution Factor]])),"",SUM(tbl_sWGA[[#This Row],[sWGA qubit '[DNA'] (ng / ul)]]*tbl_sWGA[[#This Row],[sWGA Dilution Factor]]))
A15: 12 | B15: =RIGHT(tbl_sWGA[[#This Row],[Well]],LEN(tbl_sWGA[[#This Row],[Well]])-1) -> 2 | C15: D2 | D15: =IF(Assay!$F$32=Reference!$E$56,IF(LEN(tbl_sWGA[[#This Row],[Sample ID]])>0,tbl_sWGA[[#This Row],[Sample ID]],""),IF(LEN(tbl_sWGA[[#This Row],[Extraction ID]])>0,tbl_sWGA[[#This Row],[Extraction ID]],"")) | K15: =IF(OR(ISBLANK(tbl_sWGA[[#This Row],[sWGA qubit '[DNA'] (ng / ul)]]),ISBLANK(tbl_sWGA[[#This Row],[sWGA Dilution Factor]])),"",SUM(tbl_sWGA[[#This Row],[sWGA qubit '[DNA'] (ng / ul)]]*tbl_sWGA[[#This Row],[sWGA Dilution Factor]]))
... A99: 96 | B99: =RIGHT(tbl_sWGA[[#This Row],[Well]],LEN(tbl_sWGA[[#This Row],[Well]])-1) -> 12 | C99: H12 | D99: =IF(Assay!$F$32=Reference!$E$56,IF(LEN(tbl_sWGA[[#This Row],[Sample ID]])>0,tbl_sWGA[[#This Row],[Sample ID]],""),IF(LEN(tbl_sWGA[[#This Row],[Extraction ID]])>0,tbl_sWGA[[#This Row],[Extraction ID]],"")) | K99: =IF(OR(ISBLANK(tbl_sWGA[[#This Row],[sWGA qubit '[DNA'] (ng / ul)]]),ISBLANK(tbl_sWGA[[#This Row],[sWGA Dilution Factor]])),"",SUM(tbl_sWGA[[#This Row],[sWGA qubit '[DNA'] (ng / ul)]]*tbl_sWGA[[#This Row],[sWGA Dilution Factor]]))
E100: Copy these columns to the PCR template | H100: 1 | J100: 1

Sheet Reference
A1: Instructions
A2: This template is to be used to record sWGA amplification as part of a NOMADS sequencing run.
A3: To prevent inadvertent loss of data, cells are protected from editing, you can only select unlocked cells, use tab to navigate
A5: Process
A6: 1. Enter all details into the 'Assay' (experiment level) and 'sWGA' (reaction level) tabs, ensuring all yellow highlighted cells are complete
A7: 2. Save workbook with the correct filename to the shared Google Drive folder
A14: Reference values (change only if required)
A15: Assumptions | E15: Look-ups
A16: Description | E16: DNA Polymerase
A17: DNA template mass | B17: 40 | C17: ng | E17: phi29
A18: swga template max vol | B18: =IF(swga_enzyme=Reference!$E$17, 10,12.8) -> 12.8 | C18: ul | E18: equiphi29
A20: Experiment | E20: Sample Type
A21: type | B21: sWGA | E21: Field
A22: version | B22: 11 | E22: Positive
E23: Negative
A24: Changelog from previous version
A25: Removed multiple details not being used | E25: Selected
A26: Removed usernames and projects | E26: =IF(swga_enzyme=Reference!$E$17,Reference!E36,Reference!E46) -> 45 | F26: =IF(swga_enzyme=Reference!$E$17,Reference!F36,Reference!F46) -> Prepare
E27: =IF(swga_enzyme=Reference!$E$17,Reference!E37,Reference!E47) -> 45 | F27: =IF(swga_enzyme=Reference!$E$17,Reference!F37,Reference!F47) -> 60 min
E28: =IF(swga_enzyme=Reference!$E$17,Reference!E38,Reference!E48) -> 65 | F28: =IF(swga_enzyme=Reference!$E$17,Reference!F38,Reference!F48) -> 10 min
E29: =IF(swga_enzyme=Reference!$E$17,Reference!E39,Reference!E49) -> 8 | F29: =IF(swga_enzyme=Reference!$E$17,Reference!F39,Reference!F49) -> ∞
E30: =IF(swga_enzyme=Reference!$E$17,Reference!E40,Reference!E50) -> - | F30: =IF(swga_enzyme=Reference!$E$17,Reference!F40,Reference!F50) -> -
E31: =IF(swga_enzyme=Reference!$E$17,Reference!E41,Reference!E51) -> - | F31: =IF(swga_enzyme=Reference!$E$17,Reference!F41,Reference!F51) -> -
E32: =IF(swga_enzyme=Reference!$E$17,Reference!E42,Reference!E52) -> - | F32: =IF(swga_enzyme=Reference!$E$17,Reference!F42,Reference!F52) -> -
E33: =IF(swga_enzyme=Reference!$E$17,Reference!E43,Reference!E53) -> - | F33: =IF(swga_enzyme=Reference!$E$17,Reference!F43,Reference!F53) -> -
E35: phi29 cycle
E36: 35 | F36: 5 min
E37: 34 | F37: 10 min
E38: 33 | F38: 15 min
E39: 32 | F39: 20 min
E40: 31 | F40: 30 min
E41: 30 | F41: 16 hr
E42: 65 | F42: 15 min
E43: 10 | F43: ∞
E45: equiphi29 cycle
E46: 45 | F46: Prepare
E47: 45 | F47: 60 min
E48: 65 | F48: 10 min
E49: 8 | F49: ∞
E50: - | F50: -
...

Sheet expt_metadata
A1: expt_id | B1: expt_date | C1: expt_user | D1: expt_type | E1: expt_version | F1: expt_rxns | G1: expt_notes | H1: expt_summary | I1: swga_enzyme | J1: swga_rxnvol_ul | K1: swga_targetmass_ng
A2: =IF(LEN(exp_id)=0,"",exp_id) | B2: =IF(LEN(exp_date)=0,"",exp_date) | C2: =IF(LEN(user_name)=0,"",user_name) | D2: =IF(LEN(exp_type)=0,"",exp_type) -> sWGA | E2: =IF(LEN(exp_version)=0,"",exp_version) -> 11 | F2: =IF(LEN(exp_rxns)=0,"",exp_rxns) -> 0 | G2: =IF(LEN(exp_notes)=0,"",exp_notes) | H2: =IF(LEN(exp_summary)=0,"",exp_summary) | I2: =swga_enzyme -> equiphi29 | J2: =IF(LEN(swga_rxnvol)=0,"",swga_rxnvol) -> 20 | K2: =IF(LEN(swga_targetmass)=0,"",swga_targetmass) -> 40

Sheet rxn_metadata
A1: sample_id | B1: extraction_id | C1: sample_type | D1: swga_template_ul | E1: swga_product_ngul
A2: =IF(LEN(sWGA!E4)=0,"",sWGA!E4) | B2: =IF(LEN(sWGA!F4)=0,"",sWGA!F4) | C2: =IF(LEN(sWGA!G4)=0,"",sWGA!G4) | D2: =IF(LEN(sWGA!H4)=0,"",sWGA!H4) | E2: =IF(LEN(sWGA!K4)=0,"",sWGA!K4)
A3: =IF(LEN(sWGA!E5)=0,"",sWGA!E5) | B3: =IF(LEN(sWGA!F5)=0,"",sWGA!F5) | C3: =IF(LEN(sWGA!G5)=0,"",sWGA!G5) | D3: =IF(LEN(sWGA!H5)=0,"",sWGA!H5) | E3: =IF(LEN(sWGA!K5)=0,"",sWGA!K5)
A4: =IF(LEN(sWGA!E6)=0,"",sWGA!E6) | B4: =IF(LEN(sWGA!F6)=0,"",sWGA!F6) | C4: =IF(LEN(sWGA!G6)=0,"",sWGA!G6) | D4: =IF(LEN(sWGA!H6)=0,"",sWGA!H6) | E4: =IF(LEN(sWGA!K6)=0,"",sWGA!K6)
A5: =IF(LEN(sWGA!E7)=0,"",sWGA!E7) | B5: =IF(LEN(sWGA!F7)=0,"",sWGA!F7) | C5: =IF(LEN(sWGA!G7)=0,"",sWGA!G7) | D5: =IF(LEN(sWGA!H7)=0,"",sWGA!H7) | E5: =IF(LEN(sWGA!K7)=0,"",sWGA!K7)
A6: =IF(LEN(sWGA!E8)=0,"",sWGA!E8) | B6: =IF(LEN(sWGA!F8)=0,"",sWGA!F8) | C6: =IF(LEN(sWGA!G8)=0,"",sWGA!G8) | D6: =IF(LEN(sWGA!H8)=0,"",sWGA!H8) | E6: =IF(LEN(sWGA!K8)=0,"",sWGA!K8)
A7: =IF(LEN(sWGA!E9)=0,"",sWGA!E9) | B7: =IF(LEN(sWGA!F9)=0,"",sWGA!F9) | C7: =IF(LEN(sWGA!G9)=0,"",sWGA!G9) | D7: =IF(LEN(sWGA!H9)=0,"",sWGA!H9) | E7: =IF(LEN(sWGA!K9)=0,"",sWGA!K9)
A8: =IF(LEN(sWGA!E10)=0,"",sWGA!E10) | B8: =IF(LEN(sWGA!F10)=0,"",sWGA!F10) | C8: =IF(LEN(sWGA!G10)=0,"",sWGA!G10) | D8: =IF(LEN(sWGA!H10)=0,"",sWGA!H10) | E8: =IF(LEN(sWGA!K10)=0,"",sWGA!K10)
A9: =IF(LEN(sWGA!E11)=0,"",sWGA!E11) | B9: =IF(LEN(sWGA!F11)=0,"",sWGA!F11) | C9: =IF(LEN(sWGA!G11)=0,"",sWGA!G11) | D9: =IF(LEN(sWGA!H11)=0,"",sWGA!H11) | E9: =IF(LEN(sWGA!K11)=0,"",sWGA!K11)
A10: =IF(LEN(sWGA!E12)=0,"",sWGA!E12) | B10: =IF(LEN(sWGA!F12)=0,"",sWGA!F12) | C10: =IF(LEN(sWGA!G12)=0,"",sWGA!G12) | D10: =IF(LEN(sWGA!H12)=0,"",sWGA!H12) | E10: =IF(LEN(sWGA!K12)=0,"",sWGA!K12)
A11: =IF(LEN(sWGA!E13)=0,"",sWGA!E13) | B11: =IF(LEN(sWGA!F13)=0,"",sWGA!F13) | C11: =IF(LEN(sWGA!G13)=0,"",sWGA!G13) | D11: =IF(LEN(sWGA!H13)=0,"",sWGA!H13) | E11: =IF(LEN(sWGA!K13)=0,"",sWGA!K13)
A12: =IF(LEN(sWGA!E14)=0,"",sWGA!E14) | B12: =IF(LEN(sWGA!F14)=0,"",sWGA!F14) | C12: =IF(LEN(sWGA!G14)=0,"",sWGA!G14) | D12: =IF(LEN(sWGA!H14)=0,"",sWGA!H14) | E12: =IF(LEN(sWGA!K14)=0,"",sWGA!K14)
A13: =IF(LEN(sWGA!E15)=0,"",sWGA!E15) | B13: =IF(LEN(sWGA!F15)=0,"",sWGA!F15) | C13: =IF(LEN(sWGA!G15)=0,"",sWGA!G15) | D13: =IF(LEN(sWGA!H15)=0,"",sWGA!H15) | E13: =IF(LEN(sWGA!K15)=0,"",sWGA!K15)
... A97: =IF(LEN(sWGA!E99)=0,"",sWGA!E99) | B97: =IF(LEN(sWGA!F99)=0,"",sWGA!F99) | C97: =IF(LEN(sWGA!G99)=0,"",sWGA!G99) | D97: =IF(LEN(sWGA!H99)=0,"",sWGA!H99) | E97: =IF(LEN(sWGA!K99)=0,"",sWGA!K99)
